Workbook

Sheet الإرشادات
A1: إرشادات إدخال الوحدات والمشاريع
A2: 1- اضغط على ورقة النموذج ثم انسخها
A3: 2- اضف بيانات الوحدات الى الورقة المنسوخة
A4: 3- غير اسم الورقة الى اسم المشروع
A5: 4- اضف بيانات المشروع الى ورقة المشاريع

Sheet النموذج
A1: معرف المشروع | B1: كود المشروع | C1: المالك | D1: رقم المشروع | E1: رقم الوحدة فالمشروع | F1: كود نوع الوحدة | G1: كود الوحدة | H1: المشروع | I1: نموذج الوحدة | J1: نوع الوحدة | K1: مساحة الوحدة | L1: إجمالي السعر | M1: حالة الوحدة | N1: غرف النوم | O1: عدد الحمامات | P1: مكونات الوحدة | Q1: مساحة الفناء | R1: حالة المصعد | S1: الطابق | T1: رقم العمارة | U1: مساحة الصك | V1: موعد إفتتاح المشروع | W1: مزايا | X1: رابط الموقع | Y1: الدولة | Z1: المدينة | AA1: الحي | AB1: الواجهة | AC1: بروشور المشروع | AD1: بروشور الوحدة
A2: - | B2: - | F2: =IF(J2="دور","FL", IF(J2="شقة","AP", IF(J2="فيلا","VI", IF(J2="تاون هاوس","TH","")))) | G2: =B2&"-"&I2&"-"&E2&"-"&F2 -> ----
E3: رقم الوحدة فالمشروع | I3: نموذج الوحدة | J3: نوع الوحدة | K3: مساحة الوحدة | L3: إجمالي السعر | M3: حالة الوحدة | N3: غرف النوم | O3: عدد الحمامات | P3: مكونات الوحدة | Q3: مساحة الفناء | R3: حالة المصعد | S3: الطابق | T3: رقم العمارة | U3: مساحة الصك | W3: مزايا | AB3: الواجهة | AD3: بروشور الوحدة

Sheet المشاريع
A1: معرف المشروع | B1: كود المشروع | C1: المالك | D1: رقم المشروع | E1: المشروع | F1: حالة المشروع | G1: نوع المشروع | H1: انواع الوحدات | I1: موعد إفتتاح المشروع | J1: الموقع | K1: الإتجاه | L1: الدولة | M1: المدينة | N1: الحي | O1: بروشور المشروع | P1: فيديوهات المشروع | Q1: صور المشروع | R1: المرافق | S1: عدد الوحدات | T1: عدد الوحدات المتاحة | U1: عدد الوحدات تحت الإنشاء | V1: عدد الوحدات المحجوزة | W1: عدد الوحدات المباعة | X1: متوسط قيمة الوحدة | Y1: متوسط قيمة الوحدات المتاحة | Z1: إجمالي قيمة المشروع | AA1: نسبة بيع المشروع | AB1: إجمالي قيمة تحت الإنشاء | AC1: إجمالي قيمة المتاح | AD1: إجمالي قيمة المحجوز | AE1: إجمالي قيمة المباع | AF1: السعر الأدنى | AG1: السعر الأدنى المتاح | AH1: السعر الأقصى | AI1: السعر الأقصى المتاح | AJ1: نطاق السعر | AK1: نطاق السعر المتاح | AL1: المساحة الأدنى | AM1: المساحة الأدنى المتاحة | AN1: المساحة الأقصى | AO1: المساحة الأقصى المتاحة | AP1: نطاق المساحة | AQ1: نطاق المساحة المتاحة | AR1: عدد ادنى غرف نوم | AS1: عدد ادنى غرف نوم المتاحة | AT1: عدد اقصى غرف نوم | AU1: عدد اقصى غرف نوم متاحة | AV1: نطاق غرف النوم | AW1: نطاق غرف النوم المتاحة | AX1: عدد ادنى حمامات | AY1: عدد ادنى حمامات متاحة | AZ1: عدد اقصى حمامات | BA1: عدد اقصى حمامات متاحة | BB1: نطاق الحمامات | BC1: نطاق الحمامات المتاحة
A2: 1 | B2: TAN | C2: تنال | E2: تنال - الرمال | F2: =IF(COUNTIFS('الوحدات'!B:B,B2,'الوحدات'!M:M,"متاحة")>0,"متاح", IF(COUNTIFS('الوحدات'!B:B,B2,'الوحدات'!M:M,"<>")=0, "", IF(COUNTIFS('الوحدات'!B:B,B2,'الوحدات'!M:M,"تحت الإنشاء")=COUNTIFS('الوحدات'!B:B,B2,'الوحدات'!M:M,"<>"), "تحت الإنشاء", IF(COUNTIFS('الوحدات'!B:B,B2,'الوحدات'!M:M,"تحت الإنشاء")>0, "تحت الإنشاء جزئيا", "مباعة" )))) -> متاح | G2: =IFERROR(__xludf.DUMMYFUNCTION("IF(SUMPRODUCT(('الوحدات'!B:B=B2)*REGEXMATCH(TRIM('الوحدات'!J:J),""^(تاون هاوس|دور|شقة|فيلا)$""))>0,""سكني"","""")"),"سكني") -> سكني | H2: =IFERROR(__xludf.DUMMYFUNCTION("TEXTJOIN(""-"", TRUE, UNIQUE(FILTER('الوحدات'!J:J, 'الوحدات'!B:B = B2))) "),"دور-شقة") -> دور-شقة | J2: https://maps.app.goo.gl/VQzCjvzJ9MfCPR7U9 | K2: شمال | L2: المملكة العربية السعودية | M2: الرياض | N2: الرمال | R2: صالة جلوس, مجلس | S2: =COUNTIF('الوحدات'!B:B, B2) -> 6 | T2: =COUNTIFS('الوحدات'!B:B, B2, 'الوحدات'!M:M, "متاحة") -> 6 | U2: =COUNTIFS('الوحدات'!B:B, B2, 'الوحدات'!M:M, "تحت الإنشاء") -> 0 | V2: =COUNTIFS('الوحدات'!B:B, B2, 'الوحدات'!M:M, "محجوزة") -> 0 | W2: =COUNTIFS('الوحدات'!B:B, B2, 'الوحدات'!M:M, "مباعة") -> 0 | X2: =IFERROR(AVERAGEIFS('الوحدات'!L:L, 'الوحدات'!B:B, B2), "") -> 796666.67 | Y2: =IFERROR(AVERAGEIFS('الوحدات'!L:L, 'الوحدات'!B:B, B2, 'الوحدات'!M:M, "متاحة"), "") -> 796666.67 | Z2: =IFERROR(SUMIFS('الوحدات'!L:L, 'الوحدات'!B:B, B2), "") -> 4780000 | AA2: =AE2/Z2 -> 0 | AB2: =IFERROR(SUMIFS('الوحدات'!L:L, 'الوحدات'!B:B, B2, 'الوحدات'!M:M, "تحت الإنشاء"), "") -> 0 | AC2: =IFERROR(SUMIFS('الوحدات'!L:L, 'الوحدات'!B:B, B2, 'الوحدات'!M:M, "متاحة"), "") -> 4780000 | AD2: =IFERROR(SUMIFS('الوحدات'!L:L, 'الوحدات'!B:B, B2, 'الوحدات'!M:M, "محجوزة"), "") -> 0 | AE2: =IFERROR(SUMIFS('الوحدات'!L:L, 'الوحدات'!B:B, B2, 'الوحدات'!M:M, "مباعة"), "") -> 0 | AF2: =IFERROR(MINIFS('الوحدات'!L:L, 'الوحدات'!B:B, B2), "") -> 600000 | AG2: =IFERROR(MINIFS('الوحدات'!L:L, 'الوحدات'!B:B, B2, 'الوحدات'!M:M, "متاحة"), "") -> 600000 | AH2: =IFERROR(MAXIFS('الوحدات'!L:L, 'الوحدات'!B:B, B2), "") -> 990000 | AI2: =IFERROR(MAXIFS('الوحدات'!L:L, 'الوحدات'!B:B, B2, 'الوحدات'!M:M, "متاحة"), "") -> 990000 | AJ2: =AH2&"-"&AF2 -> 990000-600000 | AK2: =AI2&"-"&AG2 -> 990000-600000 | AL2: =IFERROR(MINIFS('الوحدات'!K:K, 'الوحدات'!B:B, B2), "") -> 186 | AM2: =IFERROR(MINIFS('الوحدات'!K:K, 'الوحدات'!B:B, B2, 'الوحدات'!M:M, "متاحة"), "") -> 186 | AN2: =IFERROR(MAXIFS('الوحدات'!K:K, 'الوحدات'!B:B, B2), "") -> 258 | AO2: =IFERROR(MAXIFS('الوحدات'!K:K, 'الوحدات'!B:B, B2, 'الوحدات'!M:M, "متاحة"), "") -> 258 | AP2: =AN2&"-"&AL2 -> 258-186 | AQ2: =AO2&"-"&AM2 -> 258-186 | AR2: =IFERROR(MINIFS('الوحدات'!N:N, 'الوحدات'!B:B, B2), "") -> 2 | AS2: =IFERROR(MINIFS('الوحدات'!N:N, 'الوحدات'!B:B, B2, 'الوحدات'!M:M, "متاحة"), "") -> 2 | AT2: =IFERROR(MAXIFS('الوحدات'!N:N, 'الوحدات'!B:B, B2), "") -> 3 | AU2: =IFERROR(MAXIFS('الوحدات'!N:N, 'الوحدات'!B:B, B2, 'الوحدات'!M:M, "متاحة"), "") -> 3 | AV2: =AT2&"-"&AR2 -> 3-2 | AW2: =AU2&"-"&AS2 -> 3-2 | AX2: =IFERROR(MINIFS('الوحدات'!O:O, 'الوحدات'!B:B, B2), "") -> 2 | AY2: =IFERROR(MINIFS('الوحدات'!O:O, 'الوحدات'!B:B, B2, 'الوحدات'!M:M, "متاحة"), "") -> 2 | AZ2: =IFERROR(MAXIFS('الوحدات'!O:O, 'الوحدات'!B:B, B2), "") -> 3 | BA2: =IFERROR(MAXIFS('الوحدات'!O:O, 'الوحدات'!B:B, B2, 'الوحدات'!M:M, "متاحة"), "") -> 3 | BB2: =AZ2&"-"&AX2 -> 3-2 | BC2: =BA2&"-"&AY2 -> 3-2
A3: 2 | B3: TAR | C3: ترف | E3: ترف - الرمال | F3: =IF(COUNTIFS('الوحدات'!B:B,B3,'الوحدات'!M:M,"متاحة")>0,"متاح", IF(COUNTIFS('الوحدات'!B:B,B3,'الوحدات'!M:M,"<>")=0, "", IF(COUNTIFS('الوحدات'!B:B,B3,'الوحدات'!M:M,"تحت الإنشاء")=COUNTIFS('الوحدات'!B:B,B3,'الوحدات'!M:M,"<>"), "تحت الإنشاء", IF(COUNTIFS('الوحدات'!B:B,B3,'الوحدات'!M:M,"تحت الإنشاء")>0, "تحت الإنشاء جزئيا", "مباعة" )))) -> متاح | G3: =IFERROR(__xludf.DUMMYFUNCTION("IF(SUMPRODUCT(('الوحدات'!B:B=B3)*REGEXMATCH(TRIM('الوحدات'!J:J),""^(تاون هاوس|دور|شقة|فيلا)$""))>0,""سكني"","""")"),"سكني") -> سكني | H3: =IFERROR(__xludf.DUMMYFUNCTION("TEXTJOIN(""-"", TRUE, UNIQUE(FILTER('الوحدات'!J:J, 'الوحدات'!B:B = B3))) "),"دور-شقة") -> دور-شقة | J3: https://maps.app.goo.gl/HbNqmyyW7a6zVxRs7?g_st=ipc | K3: شمال | L3: المملكة العربية السعودية | M3: الرياض | N3: الرمال | R3: صالة جلوس, مجلس | S3: =COUNTIF('الوحدات'!B:B, B3) -> 6 | T3: =COUNTIFS('الوحدات'!B:B, B3, 'الوحدات'!M:M, "متاحة") -> 3 | U3: =COUNTIFS('الوحدات'!B:B, B3, 'الوحدات'!M:M, "تحت الإنشاء") -> 0 | V3: =COUNTIFS('الوحدات'!B:B, B3, 'الوحدات'!M:M, "محجوزة") -> 0 | W3: =COUNTIFS('الوحدات'!B:B, B3, 'الوحدات'!M:M, "مباعة") -> 3 | X3: =IFERROR(AVERAGEIFS('الوحدات'!L:L, 'الوحدات'!B:B, B3), "") -> 856333.33 | Y3: =IFERROR(AVERAGEIFS('الوحدات'!L:L, 'الوحدات'!B:B, B3, 'الوحدات'!M:M, "متاحة"), "") -> 882666.67 | Z3: =IFERROR(SUMIFS('الوحدات'!L:L, 'الوحدات'!B:B, B3), "") -> 5138000 | AA3: =AE3/Z3 -> 0.48462437 | AB3: =IFERROR(SUMIFS('الوحدات'!L:L, 'الوحدات'!B:B, B3, 'الوحدات'!M:M, "تحت الإنشاء"), "") -> 0 | AC3: =IFERROR(SUMIFS('الوحدات'!L:L, 'الوحدات'!B:B, B3, 'الوحدات'!M:M, "متاحة"), "") -> 2648000 | AD3: =IFERROR(SUMIFS('الوحدات'!L:L, 'الوحدات'!B:B, B3, 'الوحدات'!M:M, "محجوزة"), "") -> 0 | AE3: =IFERROR(SUMIFS('الوحدات'!L:L, 'الوحدات'!B:B, B3, 'الوحدات'!M:M, "مباعة"), "") -> 2490000 | AF3: =IFERROR(MINIFS('الوحدات'!L:L, 'الوحدات'!B:B, B3), "") -> 750000 | AG3: =IFERROR(MINIFS('الوحدات'!L:L, 'الوحدات'!B:B, B3, 'الوحدات'!M:M, "متاحة"), "") -> 829000 | AH3: =IFERROR(MAXIFS('الوحدات'!L:L, 'الوحدات'!B:B, B3), "") -> 990000 | AI3: =IFERROR(MAXIFS('الوحدات'!L:L, 'الوحدات'!B:B, B3, 'الوحدات'!M:M, "متاحة"), "") -> 990000 | AJ3: =AH3&"-"&AF3 -> 990000-750000 | AK3: =AI3&"-"&AG3 -> 990000-829000 | AL3: =IFERROR(MINIFS('الوحدات'!K:K, 'الوحدات'!B:B, B3), "") -> 203 | AM3: =IFERROR(MINIFS('الوحدات'!K:K, 'الوحدات'!B:B, B3, 'الوحدات'!M:M, "متاحة"), "") -> 222 | AN3: =IFERROR(MAXIFS('الوحدات'!K:K, 'الوحدات'!B:B, B3), "") -> 259 | AO3: =IFERROR(MAXIFS('الوحدات'!K:K, 'الوحدات'!B:B, B3, 'الوحدات'!M:M, "متاحة"), "") -> 259 | AP3: =AN3&"-"&AL3 -> 259-203 | AQ3: =AO3&"-"&AM3 -> 259-222 | AR3: =IFERROR(MINIFS('الوحدات'!N:N, 'الوحدات'!B:B, B3), "") -> 0 | AS3: =IFERROR(MINIFS('الوحدات'!N:N, 'الوحدات'!B:B, B3, 'الوحدات'!M:M, "متاحة"), "") -> 0 | AT3: =IFERROR(MAXIFS('الوحدات'!N:N, 'الوحدات'!B:B, B3), "") -> 0 | AU3: =IFERROR(MAXIFS('الوحدات'!N:N, 'الوحدات'!B:B, B3, 'الوحدات'!M:M, "متاحة"), "") -> 0 | AV3: =AT3&"-"&AR3 -> 0-0 | AW3: =AU3&"-"&AS3 -> 0-0 | AX3: =IFERROR(MINIFS('الوحدات'!O:O, 'الوحدات'!B:B, B3), "") -> 0 | AY3: =IFERROR(MINIFS('الوحدات'!O:O, 'الوحدات'!B:B, B3, 'الوحدات'!M:M, "متاحة"), "") -> 0 | AZ3: =IFERROR(MAXIFS('الوحدات'!O:O, 'الوحدات'!B:B, B3), "") -> 0 | BA3: =IFERROR(MAXIFS('الوحدات'!O:O, 'الوحدات'!B:B, B3, 'الوحدات'!M:M, "متاحة"), "") -> 0 | BB3: =AZ3&"-"&AX3 -> 0-0 | BC3: =BA3&"-"&AY3 -> 0-0
A4: 3 | B4: SAH | C4: سهم | E4: سهم الروضة | F4: =IF(COUNTIFS('الوحدات'!B:B,B4,'الوحدات'!M:M,"متاحة")>0,"متاح", IF(COUNTIFS('الوحدات'!B:B,B4,'الوحدات'!M:M,"<>")=0, "", IF(COUNTIFS('الوحدات'!B:B,B4,'الوحدات'!M:M,"تحت الإنشاء")=COUNTIFS('الوحدات'!B:B,B4,'الوحدات'!M:M,"<>"), "تحت الإنشاء", IF(COUNTIFS('الوحدات'!B:B,B4,'الوحدات'!M:M,"تحت الإنشاء")>0, "تحت الإنشاء جزئيا", "مباعة" )))) -> متاح | G4: =IFERROR(__xludf.DUMMYFUNCTION("IF(SUMPRODUCT(('الوحدات'!B:B=B4)*REGEXMATCH(TRIM('الوحدات'!J:J),""^(تاون هاوس|دور|شقة|فيلا)$""))>0,""سكني"","""")"),"سكني") -> سكني | H4: =IFERROR(__xludf.DUMMYFUNCTION("TEXTJOIN(""-"", TRUE, UNIQUE(FILTER('الوحدات'!J:J, 'الوحدات'!B:B = B4))) "),"دور-شقة") -> دور-شقة | J4: https://maps.app.goo.gl/oLz5KTAHqTimZF2T9 | K4: شرق | L4: المملكة العربية السعودية | M4: الرياض | N4: الروضة | O4: رداح - ادوار حي الروضة | R4: صالة جلوس, مجلس | S4: =COUNTIF('الوحدات'!B:B, B4) -> 6 | T4: =COUNTIFS('الوحدات'!B:B, B4, 'الوحدات'!M:M, "متاحة") -> 4 | U4: =COUNTIFS('الوحدات'!B:B, B4, 'الوحدات'!M:M, "تحت الإنشاء") -> 0 | V4: =COUNTIFS('الوحدات'!B:B, B4, 'الوحدات'!M:M, "محجوزة") -> 1 | W4: =COUNTIFS('الوحدات'!B:B, B4, 'الوحدات'!M:M, "مباعة") -> 1 | X4: =IFERROR(AVERAGEIFS('الوحدات'!L:L, 'الوحدات'!B:B, B4), "") -> 1420000 | Y4: =IFERROR(AVERAGEIFS('الوحدات'!L:L, 'الوحدات'!B:B, B4, 'الوحدات'!M:M, "متاحة"), "") -> 1372500 | Z4: =IFERROR(SUMIFS('الوحدات'!L:L, 'الوحدات'!B:B, B4), "") -> 8520000 | AA4: =AE4/Z4 -> 0.19248826 | AB4: =IFERROR(SUMIFS('الوحدات'!L:L, 'الوحدات'!B:B, B4, 'الوحدات'!M:M, "تحت الإنشاء"), "") -> 0 | AC4: =IFERROR(SUMIFS('الوحدات'!L:L, 'الوحدات'!B:B, B4, 'الوحدات'!M:M, "متاحة"), "") -> 5490000 | AD4: =IFERROR(SUMIFS('الوحدات'!L:L, 'الوحدات'!B:B, B4, 'الوحدات'!M:M, "محجوزة"), "") -> 1390000 | AE4: =IFERROR(SUMIFS('الوحدات'!L:L, 'الوحدات'!B:B, B4, 'الوحدات'!M:M, "مباعة"), "") -> 1640000 | AF4: =IFERROR(MINIFS('الوحدات'!L:L, 'الوحدات'!B:B, B4), "") -> 1230000 | AG4: =IFERROR(MINIFS('الوحدات'!L:L, 'الوحدات'!B:B, B4, 'الوحدات'!M:M, "متاحة"), "") -> 1230000 | AH4: =IFERROR(MAXIFS('الوحدات'!L:L, 'الوحدات'!B:B, B4), "") -> 1640000 | AI4: =IFERROR(MAXIFS('الوحدات'!L:L, 'الوحدات'!B:B, B4, 'الوحدات'!M:M, "متاحة"), "") -> 1640000 | AJ4: =AH4&"-"&AF4 -> 1640000-1230000 | AK4: =AI4&"-"&AG4 -> 1640000-1230000 | AL4: =IFERROR(MINIFS('الوحدات'!K:K, 'الوحدات'!B:B, B4), "") -> 142 | AM4: =IFERROR(MINIFS('الوحدات'!K:K, 'الوحدات'!B:B, B4, 'الوحدات'!M:M, "متاحة"), "") -> 142 | AN4: =IFERROR(MAXIFS('الوحدات'!K:K, 'الوحدات'!B:B, B4), "") -> 214 | AO4: =IFERROR(MAXIFS('الوحدات'!K:K, 'الوحدات'!B:B, B4, 'الوحدات'!M:M, "متاحة"), "") -> 214 | AP4: =AN4&"-"&AL4 -> 214-142 | AQ4: =AO4&"-"&AM4 -> 214-142 | AR4: =IFERROR(MINIFS('الوحدات'!N:N, 'الوحدات'!B:B, B4), "") -> 3 | AS4: =IFERROR(MINIFS('الوحدات'!N:N, 'الوحدات'!B:B, B4, 'الوحدات'!M:M, "متاحة"), "") -> 3 | AT4: =IFERROR(MAXIFS('الوحدات'!N:N, 'الوحدات'!B:B, B4), "") -> 4 | AU4: =IFERROR(MAXIFS('الوحدات'!N:N, 'الوحدات'!B:B, B4, 'الوحدات'!M:M, "متاحة"), "") -> 4 | AV4: =AT4&"-"&AR4 -> 4-3 | AW4: =AU4&"-"&AS4 -> 4-3 | AX4: =IFERROR(MINIFS('الوحدات'!O:O, 'الوحدات'!B:B, B4), "") -> 3 | AY4: =IFERROR(MINIFS('الوحدات'!O:O, 'الوحدات'!B:B, B4, 'الوحدات'!M:M, "متاحة"), "") -> 3 | AZ4: =IFERROR(MAXIFS('الوحدات'!O:O, 'الوحدات'!B:B, B4), "") -> 5 | BA4: =IFERROR(MAXIFS('الوحدات'!O:O, 'الوحدات'!B:B, B4, 'الوحدات'!M:M, "متاحة"), "") -> 5 | BB4: =AZ4&"-"&AX4 -> 5-3 | BC4: =BA4&"-"&AY4 -> 5-3
A5: 4 | B5: DUR | C5: درة الصفاء | E5: درة الصفاء | F5: =IF(COUNTIFS('الوحدات'!B:B,B5,'الوحدات'!M:M,"متاحة")>0,"متاح", IF(COUNTIFS('الوحدات'!B:B,B5,'الوحدات'!M:M,"<>")=0, "", IF(COUNTIFS('الوحدات'!B:B,B5,'الوحدات'!M:M,"تحت الإنشاء")=COUNTIFS('الوحدات'!B:B,B5,'الوحدات'!M:M,"<>"), "تحت الإنشاء", IF(COUNTIFS('الوحدات'!B:B,B5,'الوحدات'!M:M,"تحت الإنشاء")>0, "تحت الإنشاء جزئيا", "مباعة" )))) -> متاح | G5: =IFERROR(__xludf.DUMMYFUNCTION("IF(SUMPRODUCT(('الوحدات'!B:B=B5)*REGEXMATCH(TRIM('الوحدات'!J:J),""^(تاون هاوس|دور|شقة|فيلا)$""))>0,""سكني"","""")"),"سكني") -> سكني | H5: =IFERROR(__xludf.DUMMYFUNCTION("TEXTJOIN(""-"", TRUE, UNIQUE(FILTER('الوحدات'!J:J, 'الوحدات'!B:B = B5))) "),"فيلا") -> فيلا | J5: https://maps.app.goo.gl/qsJppfPit9RN8sY98 | K5: شرق | L5: المملكة العربية السعودية | M5: الرياض | N5: الصفاء | O5: رداح - درة الصفاء | R5: صالة جلوس, مجلس | S5: =COUNTIF('الوحدات'!B:B, B5) -> 12 | T5: =COUNTIFS('الوحدات'!B:B, B5, 'الوحدات'!M:M, "متاحة") -> 5 | U5: =COUNTIFS('الوحدات'!B:B, B5, 'الوحدات'!M:M, "تحت الإنشاء") -> 0 | V5: =COUNTIFS('الوحدات'!B:B, B5, 'الوحدات'!M:M, "محجوزة") -> 4 | W5: =COUNTIFS('الوحدات'!B:B, B5, 'الوحدات'!M:M, "مباعة") -> 3 | X5: =IFERROR(AVERAGEIFS('الوحدات'!L:L, 'الوحدات'!B:B, B5), "") -> 1693333.3 | Y5: =IFERROR(AVERAGEIFS('الوحدات'!L:L, 'الوحدات'!B:B, B5, 'الوحدات'!M:M, "متاحة"), "") -> 1664000 | Z5: =IFERROR(SUMIFS('الوحدات'!L:L, 'الوحدات'!B:B, B5), "") -> 20320000 | AA5: =AE5/Z5 -> 0.25147638 | AB5: =IFERROR(SUMIFS('الوحدات'!L:L, 'الوحدات'!B:B, B5, 'الوحدات'!M:M, "تحت الإنشاء"), "") -> 0 | AC5: =IFERROR(SUMIFS('الوحدات'!L:L, 'الوحدات'!B:B, B5, 'الوحدات'!M:M, "متاحة"), "") -> 8320000 | AD5: =IFERROR(SUMIFS('الوحدات'!L:L, 'الوحدات'!B:B, B5, 'الوحدات'!M:M, "محجوزة"), "") -> 6890000 | AE5: =IFERROR(SUMIFS('الوحدات'!L:L, 'الوحدات'!B:B, B5, 'الوحدات'!M:M, "مباعة"), "") -> 5110000 | AF5: =IFERROR(MINIFS('الوحدات'!L:L, 'الوحدات'!B:B, B5), "") -> 1580000 | AG5: =IFERROR(MINIFS('الوحدات'!L:L, 'الوحدات'!B:B, B5, 'الوحدات'!M:M, "متاحة"), "") -> 1610000 | AH5: =IFERROR(MAXIFS('الوحدات'!L:L, 'الوحدات'!B:B, B5), "") -> 1890000 | AI5: =IFERROR(MAXIFS('الوحدات'!L:L, 'الوحدات'!B:B, B5, 'الوحدات'!M:M, "متاحة"), "") -> 1880000 | AJ5: =AH5&"-"&AF5 -> 1890000-1580000 | AK5: =AI5&"-"&AG5 -> 1880000-1610000 | AL5: =IFERROR(MINIFS('الوحدات'!K:K, 'الوحدات'!B:B, B5), "") -> 249 | AM5: =IFERROR(MINIFS('الوحدات'!K:K, 'الوحدات'!B:B, B5, 'الوحدات'!M:M, "متاحة"), "") -> 249 | AN5: =IFERROR(MAXIFS('الوحدات'!K:K, 'الوحدات'!B:B, B5), "") -> 282 | AO5: =IFERROR(MAXIFS('الوحدات'!K:K, 'الوحدات'!B:B, B5, 'الوحدات'!M:M, "متاحة"), "") -> 282 | AP5: =AN5&"-"&AL5 -> 282-249 | AQ5: =AO5&"-"&AM5 -> 282-249 | AR5: =IFERROR(MINIFS('الوحدات'!N:N, 'الوحدات'!B:B, B5), "") -> 4 | AS5: =IFERROR(MINIFS('الوحدات'!N:N, 'الوحدات'!B:B, B5, 'الوحدات'!M:M, "متاحة"), "") -> 4 | AT5: =IFERROR(MAXIFS('الوحدات'!N:N, 'الوحدات'!B:B, B5), "") -> 4 | AU5: =IFERROR(MAXIFS('الوحدات'!N:N, 'الوحدات'!B:B, B5, 'الوحدات'!M:M, "متاحة"), "") -> 4 | AV5: =AT5&"-"&AR5 -> 4-4 | AW5: =AU5&"-"&AS5 -> 4-4 | AX5: =IFERROR(MINIFS('الوحدات'!O:O, 'الوحدات'!B:B, B5), "") -> 5 | AY5: =IFERROR(MINIFS('الوحدات'!O:O, 'الوحدات'!B:B, B5, 'الوحدات'!M:M, "متاحة"), "") -> 5 | AZ5: =IFERROR(MAXIFS('الوحدات'!O:O, 'الوحدات'!B:B, B5), "") -> 5 | BA5: =IFERROR(MAXIFS('الوحدات'!O:O, 'الوحدات'!B:B, B5, 'الوحدات'!M:M, "متاحة"), "") -> 5 | BB5: =AZ5&"-"&AX5 -> 5-5 | BC5: =BA5&"-"&AY5 -> 5-5
A6: 5 | B6: SAL | C6: السلام ريزدنس | E6: السلام ريزدنس | F6: =IF(COUNTIFS('الوحدات'!B:B,B6,'الوحدات'!M:M,"متاحة")>0,"متاح", IF(COUNTIFS('الوحدات'!B:B,B6,'الوحدات'!M:M,"<>")=0, "", IF(COUNTIFS('الوحدات'!B:B,B6,'الوحدات'!M:M,"تحت الإنشاء")=COUNTIFS('الوحدات'!B:B,B6,'الوحدات'!M:M,"<>"), "تحت الإنشاء", IF(COUNTIFS('الوحدات'!B:B,B6,'الوحدات'!M:M,"تحت الإنشاء")>0, "تحت الإنشاء جزئيا", "مباعة" )))) -> متاح | G6: =IFERROR(__xludf.DUMMYFUNCTION("IF(SUMPRODUCT(('الوحدات'!B:B=B6)*REGEXMATCH(TRIM('الوحدات'!J:J),""^(تاون هاوس|دور|شقة|فيلا)$""))>0,""سكني"","""")"),"سكني") -> سكني | H6: =IFERROR(__xludf.DUMMYFUNCTION("TEXTJOIN(""-"", TRUE, UNIQUE(FILTER('الوحدات'!J:J, 'الوحدات'!B:B = B6))) "),"شقة") -> شقة | J6: https://maps.app.goo.gl/CMxaMUfvXSi6TrNt5 | K6: شرق | L6: المملكة العربية السعودية | M6: الرياض | N6: السلام | O6: رداح - السلام ريزيدنس | R6: صالة جلوس, مجلس | S6: =COUNTIF('الوحدات'!B:B, B6) -> 13 | T6: =COUNTIFS('الوحدات'!B:B, B6, 'الوحدات'!M:M, "متاحة") -> 6 | U6: =COUNTIFS('الوحدات'!B:B, B6, 'الوحدات'!M:M, "تحت الإنشاء") -> 0 | V6: =COUNTIFS('الوحدات'!B:B, B6, 'الوحدات'!M:M, "محجوزة") -> 0 | W6: =COUNTIFS('الوحدات'!B:B, B6, 'الوحدات'!M:M, "مباعة") -> 7 | X6: =IFERROR(AVERAGEIFS('الوحدات'!L:L, 'الوحدات'!B:B, B6), "") -> 983538.46 | Y6: =IFERROR(AVERAGEIFS('الوحدات'!L:L, 'الوحدات'!B:B, B6, 'الوحدات'!M:M, "متاحة"), "") -> 1050000 | Z6: =IFERROR(SUMIFS('الوحدات'!L:L, 'الوحدات'!B:B, B6), "") -> 12786000 | AA6: =AE6/Z6 -> 0.50727358 | AB6: =IFERROR(SUMIFS('الوحدات'!L:L, 'الوحدات'!B:B, B6, 'الوحدات'!M:M, "تحت الإنشاء"), "") -> 0 | AC6: =IFERROR(SUMIFS('الوحدات'!L:L, 'الوحدات'!B:B, B6, 'الوحدات'!M:M, "متاحة"), "") -> 6300000 | AD6: =IFERROR(SUMIFS('الوحدات'!L:L, 'الوحدات'!B:B, B6, 'الوحدات'!M:M, "محجوزة"), "") -> 0 | AE6: =IFERROR(SUMIFS('الوحدات'!L:L, 'الوحدات'!B:B, B6, 'الوحدات'!M:M, "مباعة"), "") -> 6486000 | AF6: =IFERROR(MINIFS('الوحدات'!L:L, 'الوحدات'!B:B, B6), "") -> 830000 | AG6: =IFERROR(MINIFS('الوحدات'!L:L, 'الوحدات'!B:B, B6, 'الوحدات'!M:M, "متاحة"), "") -> 830000 | AH6: =IFERROR(MAXIFS('الوحدات'!L:L, 'الوحدات'!B:B, B6), "") -> 1330000 | AI6: =IFERROR(MAXIFS('الوحدات'!L:L, 'الوحدات'!B:B, B6, 'الوحدات'!M:M, "متاحة"), "") -> 1330000 | AJ6: =AH6&"-"&AF6 -> 1330000-830000 | AK6: =AI6&"-"&AG6 -> 1330000-830000 | AL6: =IFERROR(MINIFS('الوحدات'!K:K, 'الوحدات'!B:B, B6), "") -> 143 | AM6: =IFERROR(MINIFS('الوحدات'!K:K, 'الوحدات'!B:B, B6, 'الوحدات'!M:M, "متاحة"), "") -> 143 | AN6: =IFERROR(MAXIFS('الوحدات'!K:K, 'الوحدات'!B:B, B6), "") -> 281 | AO6: =IFERROR(MAXIFS('الوحدات'!K:K, 'الوحدات'!B:B, B6, 'الوحدات'!M:M, "متاحة"), "") -> 251 | AP6: =AN6&"-"&AL6 -> 281-143 | AQ6: =AO6&"-"&AM6 -> 251-143 | AR6: =IFERROR(MINIFS('الوحدات'!N:N, 'الوحدات'!B:B, B6), "") -> 3 | AS6: =IFERROR(MINIFS('الوحدات'!N:N, 'الوحدات'!B:B, B6, 'الوحدات'!M:M, "متاحة"), "") -> 3 | AT6: =IFERROR(MAXIFS('الوحدات'!N:N, 'الوحدات'!B:B, B6), "") -> 3 | AU6: =IFERROR(MAXIFS('الوحدات'!N:N, 'الوحدات'!B:B, B6, 'الوحدات'!M:M, "متاحة"), "") -> 3 | AV6: =AT6&"-"&AR6 -> 3-3 | AW6: =AU6&"-"&AS6 -> 3-3 | AX6: =IFERROR(MINIFS('الوحدات'!O:O, 'الوحدات'!B:B, B6), "") -> 4 | AY6: =IFERROR(MINIFS('الوحدات'!O:O, 'الوحدات'!B:B, B6, 'الوحدات'!M:M, "متاحة"), "") -> 4 | AZ6: =IFERROR(MAXIFS('الوحدات'!O:O, 'الوحدات'!B:B, B6), "") -> 4 | BA6: =IFERROR(MAXIFS('الوحدات'!O:O, 'الوحدات'!B:B, B6, 'الوحدات'!M:M, "متاحة"), "") -> 4 | BB6: =AZ6&"-"&AX6 -> 4-4 | BC6: =BA6&"-"&AY6 -> 4-4
A7: 6 | B7: MAJ79 | C7: المجالات | D7: 79 | E7: المجالات - 79 | F7: =IF(COUNTIFS('الوحدات'!B:B,B7,'الوحدات'!M:M,"متاحة")>0,"متاح", IF(COUNTIFS('الوحدات'!B:B,B7,'الوحدات'!M:M,"<>")=0, "", IF(COUNTIFS('الوحدات'!B:B,B7,'الوحدات'!M:M,"تحت الإنشاء")=COUNTIFS('الوحدات'!B:B,B7,'الوحدات'!M:M,"<>"), "تحت الإنشاء", IF(COUNTIFS('الوحدات'!B:B,B7,'الوحدات'!M:M,"تحت الإنشاء")>0, "تحت الإنشاء جزئيا", "مباعة" )))) -> متاح | G7: =IFERROR(__xludf.DUMMYFUNCTION("IF(SUMPRODUCT(('الوحدات'!B:B=B7)*REGEXMATCH(TRIM('الوحدات'!J:J),""^(تاون هاوس|دور|شقة|فيلا)$""))>0,""سكني"","""")"),"سكني") -> سكني | H7: =IFERROR(__xludf.DUMMYFUNCTION("TEXTJOIN(""-"", TRUE, UNIQUE(FILTER('الوحدات'!J:J, 'الوحدات'!B:B = B7))) "),"فيلا-دور") -> فيلا-دور | J7: https://maps.app.goo.gl/irPzaUaLrvcgyAu49 | K7: شمال | L7: المملكة العربية السعودية | M7: الرياض | N7: الصحافة | R7: صالة جلوس, مجلس, غرفة سائق | S7: =COUNTIF('الوحدات'!B:B, B7) -> 5 | T7: =COUNTIFS('الوحدات'!B:B, B7, 'الوحدات'!M:M, "متاحة") -> 5 | U7: =COUNTIFS('الوحدات'!B:B, B7, 'الوحدات'!M:M, "تحت الإنشاء") -> 0 | V7: =COUNTIFS('الوحدات'!B:B, B7, 'الوحدات'!M:M, "محجوزة") -> 0 | W7: =COUNTIFS('الوحدات'!B:B, B7, 'الوحدات'!M:M, "مباعة") -> 0 | X7: =IFERROR(AVERAGEIFS('الوحدات'!L:L, 'الوحدات'!B:B, B7), "") -> 2690000 | Y7: =IFERROR(AVERAGEIFS('الوحدات'!L:L, 'الوحدات'!B:B, B7, 'الوحدات'!M:M, "متاحة"), "") -> 2690000 | Z7: =IFERROR(SUMIFS('الوحدات'!L:L, 'الوحدات'!B:B, B7), "") -> 13450000 | AA7: =AE7/Z7 -> 0 | AB7: =IFERROR(SUMIFS('الوحدات'!L:L, 'الوحدات'!B:B, B7, 'الوحدات'!M:M, "تحت الإنشاء"), "") -> 0 | AC7: =IFERROR(SUMIFS('الوحدات'!L:L, 'الوحدات'!B:B, B7, 'الوحدات'!M:M, "متاحة"), "") -> 13450000 | AD7: =IFERROR(SUMIFS('الوحدات'!L:L, 'الوحدات'!B:B, B7, 'الوحدات'!M:M, "محجوزة"), "") -> 0 | AE7: =IFERROR(SUMIFS('الوحدات'!L:L, 'الوحدات'!B:B, B7, 'الوحدات'!M:M, "مباعة"), "") -> 0 | AF7: =IFERROR(MINIFS('الوحدات'!L:L, 'الوحدات'!B:B, B7), "") -> 1750000 | AG7: =IFERROR(MINIFS('الوحدات'!L:L, 'الوحدات'!B:B, B7, 'الوحدات'!M:M, "متاحة"), "") -> 1750000 | AH7: =IFERROR(MAXIFS('الوحدات'!L:L, 'الوحدات'!B:B, B7), "") -> 3900000 | AI7: =IFERROR(MAXIFS('الوحدات'!L:L, 'الوحدات'!B:B, B7, 'الوحدات'!M:M, "متاحة"), "") -> 3900000 | AJ7: =AH7&"-"&AF7 -> 3900000-1750000 | AK7: =AI7&"-"&AG7 -> 3900000-1750000 | AL7: =IFERROR(MINIFS('الوحدات'!K:K, 'الوحدات'!B:B, B7), "") -> 158 | AM7: =IFERROR(MINIFS('الوحدات'!K:K, 'الوحدات'!B:B, B7, 'الوحدات'!M:M, "متاحة"), "") -> 158 | AN7: =IFERROR(MAXIFS('الوحدات'!K:K, 'الوحدات'!B:B, B7), "") -> 258 | AO7: =IFERROR(MAXIFS('الوحدات'!K:K, 'الوحدات'!B:B, B7, 'الوحدات'!M:M, "متاحة"), "") -> 258 | AP7: =AN7&"-"&AL7 -> 258-158 | AQ7: =AO7&"-"&AM7 -> 258-158 | AR7: =IFERROR(MINIFS('الوحدات'!N:N, 'الوحدات'!B:B, B7), "") -> 3 | AS7: =IFERROR(MINIFS('الوحدات'!N:N, 'الوحدات'!B:B, B7, 'الوحدات'!M:M, "متاحة"), "") -> 3 | AT7: =IFERROR(MAXIFS('الوحدات'!N:N, 'الوحدات'!B:B, B7), "") -> 4 | AU7: =IFERROR(MAXIFS('الوحدات'!N:N, 'الوحدات'!B:B, B7, 'الوحدات'!M:M, "متاحة"), "") -> 4 | AV7: =AT7&"-"&AR7 -> 4-3 | AW7: =AU7&"-"&AS7 -> 4-3 | AX7: =IFERROR(MINIFS('الوحدات'!O:O, 'الوحدات'!B:B, B7), "") -> 3 | AY7: =IFERROR(MINIFS('الوحدات'!O:O, 'الوحدات'!B:B, B7, 'الوحدات'!M:M, "متاحة"), "") -> 3 | AZ7: =IFERROR(MAXIFS('الوحدات'!O:O, 'الوحدات'!B:B, B7), "") -> 6 | BA7: =IFERROR(MAXIFS('الوحدات'!O:O, 'الوحدات'!B:B, B7, 'الوحدات'!M:M, "متاحة"), "") -> 6 | BB7: =AZ7&"-"&AX7 -> 6-3 | BC7: =BA7&"-"&AY7 -> 6-3
A8: 7 | B8: ALN106 | C8: ألين | D8: 106 | E8: ألين - 106 | F8: =IF(COUNTIFS('الوحدات'!B:B,B8,'الوحدات'!M:M,"متاحة")>0,"متاح", IF(COUNTIFS('الوحدات'!B:B,B8,'الوحدات'!M:M,"<>")=0, "", IF(COUNTIFS('الوحدات'!B:B,B8,'الوحدات'!M:M,"تحت الإنشاء")=COUNTIFS('الوحدات'!B:B,B8,'الوحدات'!M:M,"<>"), "تحت الإنشاء", IF(COUNTIFS('الوحدات'!B:B,B8,'الوحدات'!M:M,"تحت الإنشاء")>0, "تحت الإنشاء جزئيا", "مباعة" )))) -> تحت الإنشاء | G8: =IFERROR(__xludf.DUMMYFUNCTION("IF(SUMPRODUCT(('الوحدات'!B:B=B8)*REGEXMATCH(TRIM('الوحدات'!J:J),""^(تاون هاوس|دور|شقة|فيلا)$""))>0,""سكني"","""")"),"سكني") -> سكني | H8: =IFERROR(__xludf.DUMMYFUNCTION("TEXTJOIN(""-"", TRUE, UNIQUE(FILTER('الوحدات'!J:J, 'الوحدات'!B:B = B8))) "),"دور") -> دور | J8: https://maps.app.goo.gl/y4PPVtti2qfr3m8z9 | K8: شرق | M8: الرياض | N8: الروضة | O8: رداح - ألين - الروضة 106 | R8: مجلس, صالة طعام, غرفة خادمة, بلكونة | S8: =COUNTIF('الوحدات'!B:B, B8) -> 2 | T8: =COUNTIFS('الوحدات'!B:B, B8, 'الوحدات'!M:M, "متاحة") -> 0 | U8: =COUNTIFS('الوحدات'!B:B, B8, 'الوحدات'!M:M, "تحت الإنشاء") -> 2 | V8: =COUNTIFS('الوحدات'!B:B, B8, 'الوحدات'!M:M, "محجوزة") -> 0 | W8: =COUNTIFS('الوحدات'!B:B, B8, 'الوحدات'!M:M, "مباعة") -> 0 | X8: =IFERROR(AVERAGEIFS('الوحدات'!L:L, 'الوحدات'!B:B, B8), "") -> 1424000 | Y8: =IFERROR(AVERAGEIFS('الوحدات'!L:L, 'الوحدات'!B:B, B8, 'الوحدات'!M:M, "متاحة"), "") | Z8: =IFERROR(SUMIFS('الوحدات'!L:L, 'الوحدات'!B:B, B8), "") -> 2848000 | AA8: =AE8/Z8 -> 0 | AB8: =IFERROR(SUMIFS('الوحدات'!L:L, 'الوحدات'!B:B, B8, 'الوحدات'!M:M, "تحت الإنشاء"), "") -> 2848000 | AC8: =IFERROR(SUMIFS('الوحدات'!L:L, 'الوحدات'!B:B, B8, 'الوحدات'!M:M, "متاحة"), "") -> 0 | AD8: =IFERROR(SUMIFS('الوحدات'!L:L, 'الوحدات'!B:B, B8, 'الوحدات'!M:M, "محجوزة"), "") -> 0 | AE8: =IFERROR(SUMIFS('الوحدات'!L:L, 'الوحدات'!B:B, B8, 'الوحدات'!M:M, "مباعة"), "") -> 0 | AF8: =IFERROR(MINIFS('الوحدات'!L:L, 'الوحدات'!B:B, B8), "") -> 1399000 | AG8: =IFERROR(MINIFS('الوحدات'!L:L, 'الوحدات'!B:B, B8, 'الوحدات'!M:M, "متاحة"), "") -> 0 | AH8: =IFERROR(MAXIFS('الوحدات'!L:L, 'الوحدات'!B:B, B8), "") -> 1449000 | AI8: =IFERROR(MAXIFS('الوحدات'!L:L, 'الوحدات'!B:B, B8, 'الوحدات'!M:M, "متاحة"), "") -> 0 | AJ8: =AH8&"-"&AF8 -> 1449000-1399000 | AK8: =AI8&"-"&AG8 -> 0-0 | AL8: =IFERROR(MINIFS('الوحدات'!K:K, 'الوحدات'!B:B, B8), "") -> 170 | AM8: =IFERROR(MINIFS('الوحدات'!K:K, 'الوحدات'!B:B, B8, 'الوحدات'!M:M, "متاحة"), "") -> 0 | AN8: =IFERROR(MAXIFS('الوحدات'!K:K, 'الوحدات'!B:B, B8), "") -> 170 | AO8: =IFERROR(MAXIFS('الوحدات'!K:K, 'الوحدات'!B:B, B8, 'الوحدات'!M:M, "متاحة"), "") -> 0 | AP8: =AN8&"-"&AL8 -> 170-170 | AQ8: =AO8&"-"&AM8 -> 0-0 | AR8: =IFERROR(MINIFS('الوحدات'!N:N, 'الوحدات'!B:B, B8), "") -> 3 | AS8: =IFERROR(MINIFS('الوحدات'!N:N, 'الوحدات'!B:B, B8, 'الوحدات'!M:M, "متاحة"), "") -> 0 | AT8: =IFERROR(MAXIFS('الوحدات'!N:N, 'الوحدات'!B:B, B8), "") -> 3 | AU8: =IFERROR(MAXIFS('الوحدات'!N:N, 'الوحدات'!B:B, B8, 'الوحدات'!M:M, "متاحة"), "") -> 0 | AV8: =AT8&"-"&AR8 -> 3-3 | AW8: =AU8&"-"&AS8 -> 0-0 | AX8: =IFERROR(MINIFS('الوحدات'!O:O, 'الوحدات'!B:B, B8), "") -> 4 | AY8: =IFERROR(MINIFS('الوحدات'!O:O, 'الوحدات'!B:B, B8, 'الوحدات'!M:M, "متاحة"), "") -> 0 | AZ8: =IFERROR(MAXIFS('الوحدات'!O:O, 'الوحدات'!B:B, B8), "") -> 4 | BA8: =IFERROR(MAXIFS('الوحدات'!O:O, 'الوحدات'!B:B, B8, 'الوحدات'!M:M, "متاحة"), "") -> 0 | BB8: =AZ8&"-"&AX8 -> 4-4 | BC8: =BA8&"-"&AY8 -> 0-0
A9: 8 | B9: ALN108 | C9: ألين | D9: 108 | E9: ألين - 108 | F9: =IF(COUNTIFS('الوحدات'!B:B,B9,'الوحدات'!M:M,"متاحة")>0,"متاح", IF(COUNTIFS('الوحدات'!B:B,B9,'الوحدات'!M:M,"<>")=0, "", IF(COUNTIFS('الوحدات'!B:B,B9,'الوحدات'!M:M,"تحت الإنشاء")=COUNTIFS('الوحدات'!B:B,B9,'الوحدات'!M:M,"<>"), "تحت الإنشاء", IF(COUNTIFS('الوحدات'!B:B,B9,'الوحدات'!M:M,"تحت الإنشاء")>0, "تحت الإنشاء جزئيا", "مباعة" )))) -> تحت الإنشاء | G9: =IFERROR(__xludf.DUMMYFUNCTION("IF(SUMPRODUCT(('الوحدات'!B:B=B9)*REGEXMATCH(TRIM('الوحدات'!J:J),""^(تاون هاوس|دور|شقة|فيلا)$""))>0,""سكني"","""")"),"سكني") -> سكني | H9: =IFERROR(__xludf.DUMMYFUNCTION("TEXTJOIN(""-"", TRUE, UNIQUE(FILTER('الوحدات'!J:J, 'الوحدات'!B:B = B9))) "),"دور") -> دور | J9: https://maps.app.goo.gl/Zv5gYWbaA7QQA23C7 | K9: شرق | L9: المملكة العربية السعودية | M9: الرياض | N9: الملز | O9: رداح - ألين - الملز 108 | R9: مجلس, صالة طعام, غرفة خادمة, بلكونة, فناء خارجي, غرفة خدمات, غرفة غسيل, صالة جلوس | S9: =COUNTIF('الوحدات'!B:B, B9) -> 6 | T9: =COUNTIFS('الوحدات'!B:B, B9, 'الوحدات'!M:M, "متاحة") -> 0 | U9: =COUNTIFS('الوحدات'!B:B, B9, 'الوحدات'!M:M, "تحت الإنشاء") -> 6 | V9: =COUNTIFS('الوحدات'!B:B, B9, 'الوحدات'!M:M, "محجوزة") -> 0 | W9: =COUNTIFS('الوحدات'!B:B, B9, 'الوحدات'!M:M, "مباعة") -> 0 | X9: =IFERROR(AVERAGEIFS('الوحدات'!L:L, 'الوحدات'!B:B, B9), "") -> 1532333.3 | Y9: =IFERROR(AVERAGEIFS('الوحدات'!L:L, 'الوحدات'!B:B, B9, 'الوحدات'!M:M, "متاحة"), "") | Z9: =IFERROR(SUMIFS('الوحدات'!L:L, 'الوحدات'!B:B, B9), "") -> 9194000 | AA9: =AE9/Z9 -> 0 | AB9: =IFERROR(SUMIFS('الوحدات'!L:L, 'الوحدات'!B:B, B9, 'الوحدات'!M:M, "تحت الإنشاء"), "") -> 9194000 | AC9: =IFERROR(SUMIFS('الوحدات'!L:L, 'الوحدات'!B:B, B9, 'الوحدات'!M:M, "متاحة"), "") -> 0 | AD9: =IFERROR(SUMIFS('الوحدات'!L:L, 'الوحدات'!B:B, B9, 'الوحدات'!M:M, "محجوزة"), "") -> 0 | AE9: =IFERROR(SUMIFS('الوحدات'!L:L, 'الوحدات'!B:B, B9, 'الوحدات'!M:M, "مباعة"), "") -> 0 | AF9: =IFERROR(MINIFS('الوحدات'!L:L, 'الوحدات'!B:B, B9), "") -> 1349000 | AG9: =IFERROR(MINIFS('الوحدات'!L:L, 'الوحدات'!B:B, B9, 'الوحدات'!M:M, "متاحة"), "") -> 0 | AH9: =IFERROR(MAXIFS('الوحدات'!L:L, 'الوحدات'!B:B, B9), "") -> 1699000 | AI9: =IFERROR(MAXIFS('الوحدات'!L:L, 'الوحدات'!B:B, B9, 'الوحدات'!M:M, "متاحة"), "") -> 0 | AJ9: =AH9&"-"&AF9 -> 1699000-1349000 | AK9: =AI9&"-"&AG9 -> 0-0 | AL9: =IFERROR(MINIFS('الوحدات'!K:K, 'الوحدات'!B:B, B9), "") -> 154 | AM9: =IFERROR(MINIFS('الوحدات'!K:K, 'الوحدات'!B:B, B9, 'الوحدات'!M:M, "متاحة"), "") -> 0 | AN9: =IFERROR(MAXIFS('الوحدات'!K:K, 'الوحدات'!B:B, B9), "") -> 179 | AO9: =IFERROR(MAXIFS('الوحدات'!K:K, 'الوحدات'!B:B, B9, 'الوحدات'!M:M, "متاحة"), "") -> 0 | AP9: =AN9&"-"&AL9 -> 179-154 | AQ9: =AO9&"-"&AM9 -> 0-0 | AR9: =IFERROR(MINIFS('الوحدات'!N:N, 'الوحدات'!B:B, B9), "") -> 3 | AS9: =IFERROR(MINIFS('الوحدات'!N:N, 'الوحدات'!B:B, B9, 'الوحدات'!M:M, "متاحة"), "") -> 0 | AT9: =IFERROR(MAXIFS('الوحدات'!N:N, 'الوحدات'!B:B, B9), "") -> 3 | AU9: =IFERROR(MAXIFS('الوحدات'!N:N, 'الوحدات'!B:B, B9, 'الوحدات'!M:M, "متاحة"), "") -> 0 | AV9: =AT9&"-"&AR9 -> 3-3 | AW9: =AU9&"-"&AS9 -> 0-0 | AX9: =IFERROR(MINIFS('الوحدات'!O:O, 'الوحدات'!B:B, B9), "") -> 3 | AY9: =IFERROR(MINIFS('الوحدات'!O:O, 'الوحدات'!B:B, B9, 'الوحدات'!M:M, "متاحة"), "") -> 0 | AZ9: =IFERROR(MAXIFS('الوحدات'!O:O, 'الوحدات'!B:B, B9), "") -> 5 | BA9: =IFERROR(MAXIFS('الوحدات'!O:O, 'الوحدات'!B:B, B9, 'الوحدات'!M:M, "متاحة"), "") -> 0 | BB9: =AZ9&"-"&AX9 -> 5-3 | BC9: =BA9&"-"&AY9 -> 0-0
A10: 9 | B10: ALN120 | C10: ألين | D10: 120 | E10: ألين - 120 | F10: =IF(COUNTIFS('الوحدات'!B:B,B10,'الوحدات'!M:M,"متاحة")>0,"متاح", IF(COUNTIFS('الوحدات'!B:B,B10,'الوحدات'!M:M,"<>")=0, "", IF(COUNTIFS('الوحدات'!B:B,B10,'الوحدات'!M:M,"تحت الإنشاء")=COUNTIFS('الوحدات'!B:B,B10,'الوحدات'!M:M,"<>"), "تحت الإنشاء", IF(COUNTIFS('الوحدات'!B:B,B10,'الوحدات'!M:M,"تحت الإنشاء")>0, "تحت الإنشاء جزئيا", "مباعة" )))) -> تحت الإنشاء | G10: =IFERROR(__xludf.DUMMYFUNCTION("IF(SUMPRODUCT(('الوحدات'!B:B=B10)*REGEXMATCH(TRIM('الوحدات'!J:J),""^(تاون هاوس|دور|شقة|فيلا)$""))>0,""سكني"","""")"),"سكني") -> سكني | H10: =IFERROR(__xludf.DUMMYFUNCTION("TEXTJOIN(""-"", TRUE, UNIQUE(FILTER('الوحدات'!J:J, 'الوحدات'!B:B = B10))) "),"شقة") -> شقة | J10: https://maps.app.goo.gl/v3gDHhxP3SsNPscp7 | K10: شمال | L10: المملكة العربية السعودية | M10: الرياض | N10: المحمدية | O10: رداح - ألين - المحمدية 120 | R10: غرفة خدمات, صالة جلوس, فناء خارجي, بلكونة | S10: =COUNTIF('الوحدات'!B:B, B10) -> 6 | T10: =COUNTIFS('الوحدات'!B:B, B10, 'الوحدات'!M:M, "متاحة") -> 0 | U10: =COUNTIFS('الوحدات'!B:B, B10, 'الوحدات'!M:M, "تحت الإنشاء") -> 6 | V10: =COUNTIFS('الوحدات'!B:B, B10, 'الوحدات'!M:M, "محجوزة") -> 0 | W10: =COUNTIFS('الوحدات'!B:B, B10, 'الوحدات'!M:M, "مباعة") -> 0 | X10: =IFERROR(AVERAGEIFS('الوحدات'!L:L, 'الوحدات'!B:B, B10), "") -> 1967333.3 | Y10: =IFERROR(AVERAGEIFS('الوحدات'!L:L, 'الوحدات'!B:B, B10, 'الوحدات'!M:M, "متاحة"), "") | Z10: =IFERROR(SUMIFS('الوحدات'!L:L, 'الوحدات'!B:B, B10), "") -> 11804000 | AA10: =AE10/Z10 -> 0 | AB10: =IFERROR(SUMIFS('الوحدات'!L:L, 'الوحدات'!B:B, B10, 'الوحدات'!M:M, "تحت الإنشاء"), "") -> 11804000 | AC10: =IFERROR(SUMIFS('الوحدات'!L:L, 'الوحدات'!B:B, B10, 'الوحدات'!M:M, "متاحة"), "") -> 0 | AD10: =IFERROR(SUMIFS('الوحدات'!L:L, 'الوحدات'!B:B, B10, 'الوحدات'!M:M, "محجوزة"), "") -> 0 | AE10: =IFERROR(SUMIFS('الوحدات'!L:L, 'الوحدات'!B:B, B10, 'الوحدات'!M:M, "مباعة"), "") -> 0 | AF10: =IFERROR(MINIFS('الوحدات'!L:L, 'الوحدات'!B:B, B10), "") -> 1799000 | AG10: =IFERROR(MINIFS('الوحدات'!L:L, 'الوحدات'!B:B, B10, 'الوحدات'!M:M, "متاحة"), "") -> 0 | AH10: =IFERROR(MAXIFS('الوحدات'!L:L, 'الوحدات'!B:B, B10), "") -> 2149000 | AI10: =IFERROR(MAXIFS('الوحدات'!L:L, 'الوحدات'!B:B, B10, 'الوحدات'!M:M, "متاحة"), "") -> 0 | AJ10: =AH10&"-"&AF10 -> 2149000-1799000 | AK10: =AI10&"-"&AG10 -> 0-0 | AL10: =IFERROR(MINIFS('الوحدات'!K:K, 'الوحدات'!B:B, B10), "") -> 136 | AM10: =IFERROR(MINIFS('الوحدات'!K:K, 'الوحدات'!B:B, B10, 'الوحدات'!M:M, "متاحة"), "") -> 0 | AN10: =IFERROR(MAXIFS('الوحدات'!K:K, 'الوحدات'!B:B, B10), "") -> 136 | AO10: =IFERROR(MAXIFS('الوحدات'!K:K, 'الوحدات'!B:B, B10, 'الوحدات'!M:M, "متاحة"), "") -> 0 | AP10: =AN10&"-"&AL10 -> 136-136 | AQ10: =AO10&"-"&AM10 -> 0-0 | AR10: =IFERROR(MINIFS('الوحدات'!N:N, 'الوحدات'!B:B, B10), "") -> 3 | AS10: =IFERROR(MINIFS('الوحدات'!N:N, 'الوحدات'!B:B, B10, 'الوحدات'!M:M, "متاحة"), "") -> 0 | AT10: =IFERROR(MAXIFS('الوحدات'!N:N, 'الوحدات'!B:B, B10), "") -> 3 | AU10: =IFERROR(MAXIFS('الوحدات'!N:N, 'الوحدات'!B:B, B10, 'الوحدات'!M:M, "متاحة"), "") -> 0 | AV10: =AT10&"-"&AR10 -> 3-3 | AW10: =AU10&"-"&AS10 -> 0-0 | AX10: =IFERROR(MINIFS('الوحدات'!O:O, 'الوحدات'!B:B, B10), "") -> 3 | AY10: =IFERROR(MINIFS('الوحدات'!O:O, 'الوحدات'!B:B, B10, 'الوحدات'!M:M, "متاحة"), "") -> 0 | AZ10: =IFERROR(MAXIFS('الوحدات'!O:O, 'الوحدات'!B:B, B10), "") -> 3 | BA10: =IFERROR(MAXIFS('الوحدات'!O:O, 'الوحدات'!B:B, B10, 'الوحدات'!M:M, "متاحة"), "") -> 0 | BB10: =AZ10&"-"&AX10 -> 3-3 | BC10: =BA10&"-"&AY10 -> 0-0
A11: 10 | B11: AIN21 | C11: ميسان | D11: 21 | E11: آين | F11: =IF(COUNTIFS('الوحدات'!B:B,B11,'الوحدات'!M:M,"متاحة")>0,"متاح", IF(COUNTIFS('الوحدات'!B:B,B11,'الوحدات'!M:M,"<>")=0, "", IF(COUNTIFS('الوحدات'!B:B,B11,'الوحدات'!M:M,"تحت الإنشاء")=COUNTIFS('الوحدات'!B:B,B11,'الوحدات'!M:M,"<>"), "تحت الإنشاء", IF(COUNTIFS('الوحدات'!B:B,B11,'الوحدات'!M:M,"تحت الإنشاء")>0, "تحت الإنشاء جزئيا", "مباعة" )))) -> متاح | G11: =IFERROR(__xludf.DUMMYFUNCTION("IF(SUMPRODUCT(('الوحدات'!B:B=B11)*REGEXMATCH(TRIM('الوحدات'!J:J),""^(تاون هاوس|دور|شقة|فيلا)$""))>0,""سكني"","""")"),"سكني") -> سكني | H11: =IFERROR(__xludf.DUMMYFUNCTION("TEXTJOIN(""-"", TRUE, UNIQUE(FILTER('الوحدات'!J:J, 'الوحدات'!B:B = B11))) "),"دور") -> دور | J11: https://goo.gl/maps/fbK93s6v1kVooZMVA | K11: شمال | L11: المملكة العربية السعودية | M11: الرياض | N11: الحمراء | S11: =COUNTIF('الوحدات'!B:B, B11) -> 6 | T11: =COUNTIFS('الوحدات'!B:B, B11, 'الوحدات'!M:M, "متاحة") -> 5 | U11: =COUNTIFS('الوحدات'!B:B, B11, 'الوحدات'!M:M, "تحت الإنشاء") -> 0 | V11: =COUNTIFS('الوحدات'!B:B, B11, 'الوحدات'!M:M, "محجوزة") -> 0 | W11: =COUNTIFS('الوحدات'!B:B, B11, 'الوحدات'!M:M, "مباعة") -> 1 | X11: =IFERROR(AVERAGEIFS('الوحدات'!L:L, 'الوحدات'!B:B, B11), "") -> 1507000 | Y11: =IFERROR(AVERAGEIFS('الوحدات'!L:L, 'الوحدات'!B:B, B11, 'الوحدات'!M:M, "متاحة"), "") -> 1507000 | Z11: =IFERROR(SUMIFS('الوحدات'!L:L, 'الوحدات'!B:B, B11), "") -> 7535000 | AA11: =AE11/Z11 -> 0 | AB11: =IFERROR(SUMIFS('الوحدات'!L:L, 'الوحدات'!B:B, B11, 'الوحدات'!M:M, "تحت الإنشاء"), "") -> 0 | AC11: =IFERROR(SUMIFS('الوحدات'!L:L, 'الوحدات'!B:B, B11, 'الوحدات'!M:M, "متاحة"), "") -> 7535000 | AD11: =IFERROR(SUMIFS('الوحدات'!L:L, 'الوحدات'!B:B, B11, 'الوحدات'!M:M, "محجوزة"), "") -> 0 | AE11: =IFERROR(SUMIFS('الوحدات'!L:L, 'الوحدات'!B:B, B11, 'الوحدات'!M:M, "مباعة"), "") -> 0 | AF11: =IFERROR(MINIFS('الوحدات'!L:L, 'الوحدات'!B:B, B11), "") -> 1245000 | AG11: =IFERROR(MINIFS('الوحدات'!L:L, 'الوحدات'!B:B, B11, 'الوحدات'!M:M, "متاحة"), "") -> 1245000 | AH11: =IFERROR(MAXIFS('الوحدات'!L:L, 'الوحدات'!B:B, B11), "") -> 1855000 | AI11: =IFERROR(MAXIFS('الوحدات'!L:L, 'الوحدات'!B:B, B11, 'الوحدات'!M:M, "متاحة"), "") -> 1855000 | AJ11: =AH11&"-"&AF11 -> 1855000-1245000 | AK11: =AI11&"-"&AG11 -> 1855000-1245000 | AL11: =IFERROR(MINIFS('الوحدات'!K:K, 'الوحدات'!B:B, B11), "") -> 188 | AM11: =IFERROR(MINIFS('الوحدات'!K:K, 'الوحدات'!B:B, B11, 'الوحدات'!M:M, "متاحة"), "") -> 188 | AN11: =IFERROR(MAXIFS('الوحدات'!K:K, 'الوحدات'!B:B, B11), "") -> 243 | AO11: =IFERROR(MAXIFS('الوحدات'!K:K, 'الوحدات'!B:B, B11, 'الوحدات'!M:M, "متاحة"), "") -> 243 | AP11: =AN11&"-"&AL11 -> 243-188 | AQ11: =AO11&"-"&AM11 -> 243-188 | AR11: =IFERROR(MINIFS('الوحدات'!N:N, 'الوحدات'!B:B, B11), "") -> 3 | AS11: =IFERROR(MINIFS('الوحدات'!N:N, 'الوحدات'!B:B, B11, 'الوحدات'!M:M, "متاحة"), "") -> 3 | AT11: =IFERROR(MAXIFS('الوحدات'!N:N, 'الوحدات'!B:B, B11), "") -> 3 | AU11: =IFERROR(MAXIFS('الوحدات'!N:N, 'الوحدات'!B:B, B11, 'الوحدات'!M:M, "متاحة"), "") -> 3 | AV11: =AT11&"-"&AR11 -> 3-3 | AW11: =AU11&"-"&AS11 -> 3-3 | AX11: =IFERROR(MINIFS('الوحدات'!O:O, 'الوحدات'!B:B, B11), "") -> 0 | AY11: =IFERROR(MINIFS('الوحدات'!O:O, 'الوحدات'!B:B, B11, 'الوحدات'!M:M, "متاحة"), "") -> 0 | AZ11: =IFERROR(MAXIFS('الوحدات'!O:O, 'الوحدات'!B:B, B11), "") -> 0 | BA11: =IFERROR(MAXIFS('الوحدات'!O:O, 'الوحدات'!B:B, B11, 'الوحدات'!M:M, "متاحة"), "") -> 0 | BB11: =AZ11&"-"&AX11 -> 0-0 | BC11: =BA11&"-"&AY11 -> 0-0
A12: 11 | B12: SER | C12: يمامة | E12: سيرين | F12: =IF(COUNTIFS('الوحدات'!B:B,B12,'الوحدات'!M:M,"متاحة")>0,"متاح", IF(COUNTIFS('الوحدات'!B:B,B12,'الوحدات'!M:M,"<>")=0, "", IF(COUNTIFS('الوحدات'!B:B,B12,'الوحدات'!M:M,"تحت الإنشاء")=COUNTIFS('الوحدات'!B:B,B12,'الوحدات'!M:M,"<>"), "تحت الإنشاء", IF(COUNTIFS('الوحدات'!B:B,B12,'الوحدات'!M:M,"تحت الإنشاء")>0, "تحت الإنشاء جزئيا", "مباعة" )))) -> متاح | G12: =IFERROR(__xludf.DUMMYFUNCTION("IF(SUMPRODUCT(('الوحدات'!B:B=B12)*REGEXMATCH(TRIM('الوحدات'!J:J),""^(تاون هاوس|دور|شقة|فيلا)$""))>0,""سكني"","""")"),"سكني") -> سكني | H12: =IFERROR(__xludf.DUMMYFUNCTION("TEXTJOIN(""-"", TRUE, UNIQUE(FILTER('الوحدات'!J:J, 'الوحدات'!B:B = B12))) "),"فيلا") -> فيلا | J12: https://maps.app.goo.gl/5yYbPMnuG8Xk46Kf8?g_st=ipc | K12: شرق | L12: المملكة العربية السعودية | M12: الرياض | N12: الصفا | R12: غرفة سائق, غرفة خادمة, غرفة غسيل, صالة طعام, غرفة خدمات, صالة جلوس, مجلس | S12: =COUNTIF('الوحدات'!B:B, B12) -> 11 | T12: =COUNTIFS('الوحدات'!B:B, B12, 'الوحدات'!M:M, "متاحة") -> 11 | U12: =COUNTIFS('الوحدات'!B:B, B12, 'الوحدات'!M:M, "تحت الإنشاء") -> 0 | V12: =COUNTIFS('الوحدات'!B:B, B12, 'الوحدات'!M:M, "محجوزة") -> 0 | W12: =COUNTIFS('الوحدات'!B:B, B12, 'الوحدات'!M:M, "مباعة") -> 0 | X12: =IFERROR(AVERAGEIFS('الوحدات'!L:L, 'الوحدات'!B:B, B12), "") -> 2150000 | Y12: =IFERROR(AVERAGEIFS('الوحدات'!L:L, 'الوحدات'!B:B, B12, 'الوحدات'!M:M, "متاحة"), "") -> 2150000 | Z12: =IFERROR(SUMIFS('الوحدات'!L:L, 'الوحدات'!B:B, B12), "") -> 23650000 | AA12: =AE12/Z12 -> 0 | AB12: =IFERROR(SUMIFS('الوحدات'!L:L, 'الوحدات'!B:B, B12, 'الوحدات'!M:M, "تحت الإنشاء"), "") -> 0 | AC12: =IFERROR(SUMIFS('الوحدات'!L:L, 'الوحدات'!B:B, B12, 'الوحدات'!M:M, "متاحة"), "") -> 23650000 | AD12: =IFERROR(SUMIFS('الوحدات'!L:L, 'الوحدات'!B:B, B12, 'الوحدات'!M:M, "محجوزة"), "") -> 0 | AE12: =IFERROR(SUMIFS('الوحدات'!L:L, 'الوحدات'!B:B, B12, 'الوحدات'!M:M, "مباعة"), "") -> 0 | AF12: =IFERROR(MINIFS('الوحدات'!L:L, 'الوحدات'!B:B, B12), "") -> 2150000 | AG12: =IFERROR(MINIFS('الوحدات'!L:L, 'الوحدات'!B:B, B12, 'الوحدات'!M:M, "متاحة"), "") -> 2150000 | AH12: =IFERROR(MAXIFS('الوحدات'!L:L, 'الوحدات'!B:B, B12), "") -> 2150000 | AI12: =IFERROR(MAXIFS('الوحدات'!L:L, 'الوحدات'!B:B, B12, 'الوحدات'!M:M, "متاحة"), "") -> 2150000 | AJ12: =AH12&"-"&AF12 -> 2150000-2150000 | AK12: =AI12&"-"&AG12 -> 2150000-2150000 | AL12: =IFERROR(MINIFS('الوحدات'!K:K, 'الوحدات'!B:B, B12), "") -> 200 | AM12: =IFERROR(MINIFS('الوحدات'!K:K, 'الوحدات'!B:B, B12, 'الوحدات'!M:M, "متاحة"), "") -> 200 | AN12: =IFERROR(MAXIFS('الوحدات'!K:K, 'الوحدات'!B:B, B12), "") -> 200 | AO12: =IFERROR(MAXIFS('الوحدات'!K:K, 'الوحدات'!B:B, B12, 'الوحدات'!M:M, "متاحة"), "") -> 200 | AP12: =AN12&"-"&AL12 -> 200-200 | AQ12: =AO12&"-"&AM12 -> 200-200 | AR12: =IFERROR(MINIFS('الوحدات'!N:N, 'الوحدات'!B:B, B12), "") -> 5 | AS12: =IFERROR(MINIFS('الوحدات'!N:N, 'الوحدات'!B:B, B12, 'الوحدات'!M:M, "متاحة"), "") -> 5 | AT12: =IFERROR(MAXIFS('الوحدات'!N:N, 'الوحدات'!B:B, B12), "") -> 5 | AU12: =IFERROR(MAXIFS('الوحدات'!N:N, 'الوحدات'!B:B, B12, 'الوحدات'!M:M, "متاحة"), "") -> 5 | AV12: =AT12&"-"&AR12 -> 5-5 | AW12: =AU12&"-"&AS12 -> 5-5 | AX12: =IFERROR(MINIFS('الوحدات'!O:O, 'الوحدات'!B:B, B12), "") -> 6 | AY12: =IFERROR(MINIFS('الوحدات'!O:O, 'الوحدات'!B:B, B12, 'الوحدات'!M:M, "متاحة"), "") -> 6 | AZ12: =IFERROR(MAXIFS('الوحدات'!O:O, 'الوحدات'!B:B, B12), "") -> 6 | BA12: =IFERROR(MAXIFS('الوحدات'!O:O, 'الوحدات'!B:B, B12, 'الوحدات'!M:M, "متاحة"), "") -> 6 | BB12: =AZ12&"-"&AX12 -> 6-6 | BC12: =BA12&"-"&AY12 -> 6-6
A13: 12 | B13: HBS | C13: الحبيب | E13: الحبيب | F13: =IF(COUNTIFS('الوحدات'!B:B,B13,'الوحدات'!M:M,"متاحة")>0,"متاح", IF(COUNTIFS('الوحدات'!B:B,B13,'الوحدات'!M:M,"<>")=0, "", IF(COUNTIFS('الوحدات'!B:B,B13,'الوحدات'!M:M,"تحت الإنشاء")=COUNTIFS('الوحدات'!B:B,B13,'الوحدات'!M:M,"<>"), "تحت الإنشاء", IF(COUNTIFS('الوحدات'!B:B,B13,'الوحدات'!M:M,"تحت الإنشاء")>0, "تحت الإنشاء جزئيا", "مباعة" )))) -> متاح | G13: =IFERROR(__xludf.DUMMYFUNCTION("IF(SUMPRODUCT(('الوحدات'!B:B=B13)*REGEXMATCH(TRIM('الوحدات'!J:J),""^(تاون هاوس|دور|شقة|فيلا)$""))>0,""سكني"","""")"),"سكني") -> سكني | H13: =IFERROR(__xludf.DUMMYFUNCTION("TEXTJOIN(""-"", TRUE, UNIQUE(FILTER('الوحدات'!J:J, 'الوحدات'!B:B = B13))) "),"فيلا") -> فيلا | K13: شرق | L13: المملكة العربية السعودية | M13: الرياض | N13: الصفا | S13: =COUNTIF('الوحدات'!B:B, B13) -> 2 | T13: =COUNTIFS('الوحدات'!B:B, B13, 'الوحدات'!M:M, "متاحة") -> 2 | U13: =COUNTIFS('الوحدات'!B:B, B13, 'الوحدات'!M:M, "تحت الإنشاء") -> 0 | V13: =COUNTIFS('الوحدات'!B:B, B13, 'الوحدات'!M:M, "محجوزة") -> 0 | W13: =COUNTIFS('الوحدات'!B:B, B13, 'الوحدات'!M:M, "مباعة") -> 0 | X13: =IFERROR(AVERAGEIFS('الوحدات'!L:L, 'الوحدات'!B:B, B13), "") -> 2390000 | Y13: =IFERROR(AVERAGEIFS('الوحدات'!L:L, 'الوحدات'!B:B, B13, 'الوحدات'!M:M, "متاحة"), "") -> 2390000 | Z13: =IFERROR(SUMIFS('الوحدات'!L:L, 'الوحدات'!B:B, B13), "") -> 4780000 | AA13: =AE13/Z13 -> 0 | AB13: =IFERROR(SUMIFS('الوحدات'!L:L, 'الوحدات'!B:B, B13, 'الوحدات'!M:M, "تحت الإنشاء"), "") -> 0 | AC13: =IFERROR(SUMIFS('الوحدات'!L:L, 'الوحدات'!B:B, B13, 'الوحدات'!M:M, "متاحة"), "") -> 4780000 | AD13: =IFERROR(SUMIFS('الوحدات'!L:L, 'الوحدات'!B:B, B13, 'الوحدات'!M:M, "محجوزة"), "") -> 0 | AE13: =IFERROR(SUMIFS('الوحدات'!L:L, 'الوحدات'!B:B, B13, 'الوحدات'!M:M, "مباعة"), "") -> 0 | AF13: =IFERROR(MINIFS('الوحدات'!L:L, 'الوحدات'!B:B, B13), "") -> 2390000 | AG13: =IFERROR(MINIFS('الوحدات'!L:L, 'الوحدات'!B:B, B13, 'الوحدات'!M:M, "متاحة"), "") -> 2390000 | AH13: =IFERROR(MAXIFS('الوحدات'!L:L, 'الوحدات'!B:B, B13), "") -> 2390000 | AI13: =IFERROR(MAXIFS('الوحدات'!L:L, 'الوحدات'!B:B, B13, 'الوحدات'!M:M, "متاحة"), "") -> 2390000 | AJ13: =AH13&"-"&AF13 -> 2390000-2390000 | AK13: =AI13&"-"&AG13 -> 2390000-2390000 | AL13: =IFERROR(MINIFS('الوحدات'!K:K, 'الوحدات'!B:B, B13), "") -> 200 | AM13: =IFERROR(MINIFS('الوحدات'!K:K, 'الوحدات'!B:B, B13, 'الوحدات'!M:M, "متاحة"), "") -> 200 | AN13: =IFERROR(MAXIFS('الوحدات'!K:K, 'الوحدات'!B:B, B13), "") -> 200 | AO13: =IFERROR(MAXIFS('الوحدات'!K:K, 'الوحدات'!B:B, B13, 'الوحدات'!M:M, "متاحة"), "") -> 200 | AP13: =AN13&"-"&AL13 -> 200-200 | AQ13: =AO13&"-"&AM13 -> 200-200 | AR13: =IFERROR(MINIFS('الوحدات'!N:N, 'الوحدات'!B:B, B13), "") -> 0 | AS13: =IFERROR(MINIFS('الوحدات'!N:N, 'الوحدات'!B:B, B13, 'الوحدات'!M:M, "متاحة"), "") -> 0 | AT13: =IFERROR(MAXIFS('الوحدات'!N:N, 'الوحدات'!B:B, B13), "") -> 0 | AU13: =IFERROR(MAXIFS('الوحدات'!N:N, 'الوحدات'!B:B, B13, 'الوحدات'!M:M, "متاحة"), "") -> 0 | AV13: =AT13&"-"&AR13 -> 0-0 | AW13: =AU13&"-"&AS13 -> 0-0 | AX13: =IFERROR(MINIFS('الوحدات'!O:O, 'الوحدات'!B:B, B13), "") -> 0 | AY13: =IFERROR(MINIFS('الوحدات'!O:O, 'الوحدات'!B:B, B13, 'الوحدات'!M:M, "متاحة"), "") -> 0 | AZ13: =IFERROR(MAXIFS('الوحدات'!O:O, 'الوحدات'!B:B, B13), "") -> 0 | BA13: =IFERROR(MAXIFS('الوحدات'!O:O, 'الوحدات'!B:B, B13, 'الوحدات'!M:M, "متاحة"), "") -> 0 | BB13: =AZ13&"-"&AX13 -> 0-0 | BC13: =BA13&"-"&AY13 -> 0-0
A14: 13 | B14: MAJ80 | C14: المجالات | D14: 80 | E14: المجالات - 80 | F14: =IF(COUNTIFS('الوحدات'!B:B,B14,'الوحدات'!M:M,"متاحة")>0,"متاح", IF(COUNTIFS('الوحدات'!B:B,B14,'الوحدات'!M:M,"<>")=0, "", IF(COUNTIFS('الوحدات'!B:B,B14,'الوحدات'!M:M,"تحت الإنشاء")=COUNTIFS('الوحدات'!B:B,B14,'الوحدات'!M:M,"<>"), "تحت الإنشاء", IF(COUNTIFS('الوحدات'!B:B,B14,'الوحدات'!M:M,"تحت الإنشاء")>0, "تحت الإنشاء جزئيا", "مباعة" )))) -> متاح | G14: =IFERROR(__xludf.DUMMYFUNCTION("IF(SUMPRODUCT(('الوحدات'!B:B=B14)*REGEXMATCH(TRIM('الوحدات'!J:J),""^(تاون هاوس|دور|شقة|فيلا)$""))>0,""سكني"","""")"),"سكني") -> سكني | H14: =IFERROR(__xludf.DUMMYFUNCTION("TEXTJOIN(""-"", TRUE, UNIQUE(FILTER('الوحدات'!J:J, 'الوحدات'!B:B = B14))) "),"تاون هاوس") -> تاون هاوس | J14: https://maps.app.goo.gl/KhDLpCiJxxoQ1rnf8 | K14: شمال | L14: المملكة العربية السعودية | M14: الرياض | N14: النرجس | R14: صالة جلوس, مجلس, صالة طعام, فناء خارجي, بلكونة | S14: =COUNTIF('الوحدات'!B:B, B14) -> 24 | T14: =COUNTIFS('الوحدات'!B:B, B14, 'الوحدات'!M:M, "متاحة") -> 24 | U14: =COUNTIFS('الوحدات'!B:B, B14, 'الوحدات'!M:M, "تحت الإنشاء") -> 0 | V14: =COUNTIFS('الوحدات'!B:B, B14, 'الوحدات'!M:M, "محجوزة") -> 0 | W14: =COUNTIFS('الوحدات'!B:B, B14, 'الوحدات'!M:M, "مباعة") -> 0 | X14: =IFERROR(AVERAGEIFS('الوحدات'!L:L, 'الوحدات'!B:B, B14), "") -> 2206250 | Y14: =IFERROR(AVERAGEIFS('الوحدات'!L:L, 'الوحدات'!B:B, B14, 'الوحدات'!M:M, "متاحة"), "") -> 2206250 | Z14: =IFERROR(SUMIFS('الوحدات'!L:L, 'الوحدات'!B:B, B14), "") -> 52950000 | AA14: =AE14/Z14 -> 0 | AB14: =IFERROR(SUMIFS('الوحدات'!L:L, 'الوحدات'!B:B, B14, 'الوحدات'!M:M, "تحت الإنشاء"), "") -> 0 | AC14: =IFERROR(SUMIFS('الوحدات'!L:L, 'الوحدات'!B:B, B14, 'الوحدات'!M:M, "متاحة"), "") -> 52950000 | AD14: =IFERROR(SUMIFS('الوحدات'!L:L, 'الوحدات'!B:B, B14, 'الوحدات'!M:M, "محجوزة"), "") -> 0 | AE14: =IFERROR(SUMIFS('الوحدات'!L:L, 'الوحدات'!B:B, B14, 'الوحدات'!M:M, "مباعة"), "") -> 0 | AF14: =IFERROR(MINIFS('الوحدات'!L:L, 'الوحدات'!B:B, B14), "") -> 2175000 | AG14: =IFERROR(MINIFS('الوحدات'!L:L, 'الوحدات'!B:B, B14, 'الوحدات'!M:M, "متاحة"), "") -> 2175000 | AH14: =IFERROR(MAXIFS('الوحدات'!L:L, 'الوحدات'!B:B, B14), "") -> 2425000 | AI14: =IFERROR(MAXIFS('الوحدات'!L:L, 'الوحدات'!B:B, B14, 'الوحدات'!M:M, "متاحة"), "") -> 2425000 | AJ14: =AH14&"-"&AF14 -> 2425000-2175000 | AK14: =AI14&"-"&AG14 -> 2425000-2175000 | AL14: =IFERROR(MINIFS('الوحدات'!K:K, 'الوحدات'!B:B, B14), "") -> 384 | AM14: =IFERROR(MINIFS('الوحدات'!K:K, 'الوحدات'!B:B, B14, 'الوحدات'!M:M, "متاحة"), "") -> 384 | AN14: =IFERROR(MAXIFS('الوحدات'!K:K, 'الوحدات'!B:B, B14), "") -> 517 | AO14: =IFERROR(MAXIFS('الوحدات'!K:K, 'الوحدات'!B:B, B14, 'الوحدات'!M:M, "متاحة"), "") -> 517 | AP14: =AN14&"-"&AL14 -> 517-384 | AQ14: =AO14&"-"&AM14 -> 517-384 | AR14: =IFERROR(MINIFS('الوحدات'!N:N, 'الوحدات'!B:B, B14), "") -> 3 | AS14: =IFERROR(MINIFS('الوحدات'!N:N, 'الوحدات'!B:B, B14, 'الوحدات'!M:M, "متاحة"), "") -> 3 | AT14: =IFERROR(MAXIFS('الوحدات'!N:N, 'الوحدات'!B:B, B14), "") -> 3 | AU14: =IFERROR(MAXIFS('الوحدات'!N:N, 'الوحدات'!B:B, B14, 'الوحدات'!M:M, "متاحة"), "") -> 3 | AV14: =AT14&"-"&AR14 -> 3-3 | AW14: =AU14&"-"&AS14 -> 3-3 | AX14: =IFERROR(MINIFS('الوحدات'!O:O, 'الوحدات'!B:B, B14), "") -> 5 | AY14: =IFERROR(MINIFS('الوحدات'!O:O, 'الوحدات'!B:B, B14, 'الوحدات'!M:M, "متاحة"), "") -> 5 | AZ14: =IFERROR(MAXIFS('الوحدات'!O:O, 'الوحدات'!B:B, B14), "") -> 5 | BA14: =IFERROR(MAXIFS('الوحدات'!O:O, 'الوحدات'!B:B, B14, 'الوحدات'!M:M, "متاحة"), "") -> 5 | BB14: =AZ14&"-"&AX14 -> 5-5 | BC14: =BA14&"-"&AY14 -> 5-5
A15: 14 | B15: ALN88 | C15: ألين | D15: 88 | E15: ="ألين - "&D15 -> ألين - 88 | F15: =IF(COUNTIFS('الوحدات'!B:B,B15,'الوحدات'!M:M,"متاحة")>0,"متاح", IF(COUNTIFS('الوحدات'!B:B,B15,'الوحدات'!M:M,"<>")=0, "", IF(COUNTIFS('الوحدات'!B:B,B15,'الوحدات'!M:M,"تحت الإنشاء")=COUNTIFS('الوحدات'!B:B,B15,'الوحدات'!M:M,"<>"), "تحت الإنشاء", IF(COUNTIFS('الوحدات'!B:B,B15,'الوحدات'!M:M,"تحت الإنشاء")>0, "تحت الإنشاء جزئيا", "مباعة" )))) -> متاح | G15: =IFERROR(__xludf.DUMMYFUNCTION("IF(SUMPRODUCT(('الوحدات'!B:B=B15)*REGEXMATCH(TRIM('الوحدات'!J:J),""^(تاون هاوس|دور|شقة|فيلا)$""))>0,""سكني"","""")"),"سكني") -> سكني | H15: =IFERROR(__xludf.DUMMYFUNCTION("TEXTJOIN(""-"", TRUE, UNIQUE(FILTER('الوحدات'!J:J, 'الوحدات'!B:B = B15))) "),"شقة") -> شقة | J15: https://maps.app.goo.gl/s9q4cMjhhMpxySdb9 | K15: شمال | L15: المملكة العربية السعودية | M15: الرياض | N15: الازدهار | O15: https://aleen.cc/Upload/88/details.pdf | S15: =COUNTIF('الوحدات'!B:B, B15) -> 1 | T15: =COUNTIFS('الوحدات'!B:B, B15, 'الوحدات'!M:M, "متاحة") -> 1 | U15: =COUNTIFS('الوحدات'!B:B, B15, 'الوحدات'!M:M, "تحت الإنشاء") -> 0 | V15: =COUNTIFS('الوحدات'!B:B, B15, 'الوحدات'!M:M, "محجوزة") -> 0 | W15: =COUNTIFS('الوحدات'!B:B, B15, 'الوحدات'!M:M, "مباعة") -> 0 | X15: =IFERROR(AVERAGEIFS('الوحدات'!L:L, 'الوحدات'!B:B, B15), "") -> 1499000 | Y15: =IFERROR(AVERAGEIFS('الوحدات'!L:L, 'الوحدات'!B:B, B15, 'الوحدات'!M:M, "متاحة"), "") -> 1499000 | Z15: =IFERROR(SUMIFS('الوحدات'!L:L, 'الوحدات'!B:B, B15), "") -> 1499000 | AA15: =AE15/Z15 -> 0 | AB15: =IFERROR(SUMIFS('الوحدات'!L:L, 'الوحدات'!B:B, B15, 'الوحدات'!M:M, "تحت الإنشاء"), "") -> 0 | AC15: =IFERROR(SUMIFS('الوحدات'!L:L, 'الوحدات'!B:B, B15, 'الوحدات'!M:M, "متاحة"), "") -> 1499000 | AD15: =IFERROR(SUMIFS('الوحدات'!L:L, 'الوحدات'!B:B, B15, 'الوحدات'!M:M, "محجوزة"), "") -> 0 | AE15: =IFERROR(SUMIFS('الوحدات'!L:L, 'الوحدات'!B:B, B15, 'الوحدات'!M:M, "مباعة"), "") -> 0 | AF15: =IFERROR(MINIFS('الوحدات'!L:L, 'الوحدات'!B:B, B15), "") -> 1499000 | AG15: =IFERROR(MINIFS('الوحدات'!L:L, 'الوحدات'!B:B, B15, 'الوحدات'!M:M, "متاحة"), "") -> 1499000 | AH15: =IFERROR(MAXIFS('الوحدات'!L:L, 'الوحدات'!B:B, B15), "") -> 1499000 | AI15: =IFERROR(MAXIFS('الوحدات'!L:L, 'الوحدات'!B:B, B15, 'الوحدات'!M:M, "متاحة"), "") -> 1499000 | AJ15: =AH15&"-"&AF15 -> 1499000-1499000 | AK15: =AI15&"-"&AG15 -> 1499000-1499000 | AL15: =IFERROR(MINIFS('الوحدات'!K:K, 'الوحدات'!B:B, B15), "") -> 109 | AM15: =IFERROR(MINIFS('الوحدات'!K:K, 'الوحدات'!B:B, B15, 'الوحدات'!M:M, "متاحة"), "") -> 109 | AN15: =IFERROR(MAXIFS('الوحدات'!K:K, 'الوحدات'!B:B, B15), "") -> 109 | AO15: =IFERROR(MAXIFS('الوحدات'!K:K, 'الوحدات'!B:B, B15, 'الوحدات'!M:M, "متاحة"), "") -> 109 | AP15: =AN15&"-"&AL15 -> 109-109 | AQ15: =AO15&"-"&AM15 -> 109-109 | AR15: =IFERROR(MINIFS('الوحدات'!N:N, 'الوحدات'!B:B, B15), "") -> 3 | AS15: =IFERROR(MINIFS('الوحدات'!N:N, 'الوحدات'!B:B, B15, 'الوحدات'!M:M, "متاحة"), "") -> 3 | AT15: =IFERROR(MAXIFS('الوحدات'!N:N, 'الوحدات'!B:B, B15), "") -> 3 | AU15: =IFERROR(MAXIFS('الوحدات'!N:N, 'الوحدات'!B:B, B15, 'الوحدات'!M:M, "متاحة"), "") -> 3 | AV15: =AT15&"-"&AR15 -> 3-3 | AW15: =AU15&"-"&AS15 -> 3-3 | AX15: =IFERROR(MINIFS('الوحدات'!O:O, 'الوحدات'!B:B, B15), "") -> 2 | AY15: =IFERROR(MINIFS('الوحدات'!O:O, 'الوحدات'!B:B, B15, 'الوحدات'!M:M, "متاحة"), "") -> 2 | AZ15: =IFERROR(MAXIFS('الوحدات'!O:O, 'الوحدات'!B:B, B15), "") -> 2 | BA15: =IFERROR(MAXIFS('الوحدات'!O:O, 'الوحدات'!B:B, B15, 'الوحدات'!M:M, "متاحة"), "") -> 2 | BB15: =AZ15&"-"&AX15 -> 2-2 | BC15: =BA15&"-"&AY15 -> 2-2
A16: 15 | B16: ALN102 | C16: ألين | D16: 102 | E16: ="ألين - "&D16 -> ألين - 102 | F16: =IF(COUNTIFS('الوحدات'!B:B,B16,'الوحدات'!M:M,"متاحة")>0,"متاح", IF(COUNTIFS('الوحدات'!B:B,B16,'الوحدات'!M:M,"<>")=0, "", IF(COUNTIFS('الوحدات'!B:B,B16,'الوحدات'!M:M,"تحت الإنشاء")=COUNTIFS('الوحدات'!B:B,B16,'الوحدات'!M:M,"<>"), "تحت الإنشاء", IF(COUNTIFS('الوحدات'!B:B,B16,'الوحدات'!M:M,"تحت الإنشاء")>0, "تحت الإنشاء جزئيا", "مباعة" )))) -> تحت الإنشاء | G16: =IFERROR(__xludf.DUMMYFUNCTION("IF(SUMPRODUCT(('الوحدات'!B:B=B16)*REGEXMATCH(TRIM('الوحدات'!J:J),""^(تاون هاوس|دور|شقة|فيلا)$""))>0,""سكني"","""")"),"سكني") -> سكني | H16: =IFERROR(__xludf.DUMMYFUNCTION("TEXTJOIN(""-"", TRUE, UNIQUE(FILTER('الوحدات'!J:J, 'الوحدات'!B:B = B16))) "),"شقة") -> شقة | J16: https://www.google.com/maps/place/24%C2%B046'18.9%22N+46%C2%B037'56.3%22E/@24.7719167,46.6323056,1376m/data=!3m2!1e3!4b1!4m4!3m3!8m2!3d24.7719167!4d46.6323056!5m1!1e1?authuser=0&entry=tts&g_ep=EgoyMDI1MDYyMy4yIPu8ASoASAFQAw%3D%3D&skid=06f74f57-7ddc-40a6-9eae-6803a2eeab30 | K16: شمال | L16: المملكة العربية السعودية | M16: الرياض | N16: العقيق | O16: https://aleen.cc/Upload/102/details.pdf | S16: =COUNTIF('الوحدات'!B:B, B16) -> 2 | T16: =COUNTIFS('الوحدات'!B:B, B16, 'الوحدات'!M:M, "متاحة") -> 0 | U16: =COUNTIFS('الوحدات'!B:B, B16, 'الوحدات'!M:M, "تحت الإنشاء") -> 2 | V16: =COUNTIFS('الوحدات'!B:B, B16, 'الوحدات'!M:M, "محجوزة") -> 0 | W16: =COUNTIFS('الوحدات'!B:B, B16, 'الوحدات'!M:M, "مباعة") -> 0 | X16: =IFERROR(AVERAGEIFS('الوحدات'!L:L, 'الوحدات'!B:B, B16), "") -> 1739000 | Y16: =IFERROR(AVERAGEIFS('الوحدات'!L:L, 'الوحدات'!B:B, B16, 'الوحدات'!M:M, "متاحة"), "") | Z16: =IFERROR(SUMIFS('الوحدات'!L:L, 'الوحدات'!B:B, B16), "") -> 3478000 | AA16: =AE16/Z16 -> 0 | AB16: =IFERROR(SUMIFS('الوحدات'!L:L, 'الوحدات'!B:B, B16, 'الوحدات'!M:M, "تحت الإنشاء"), "") -> 3478000 | AC16: =IFERROR(SUMIFS('الوحدات'!L:L, 'الوحدات'!B:B, B16, 'الوحدات'!M:M, "متاحة"), "") -> 0 | AD16: =IFERROR(SUMIFS('الوحدات'!L:L, 'الوحدات'!B:B, B16, 'الوحدات'!M:M, "محجوزة"), "") -> 0 | AE16: =IFERROR(SUMIFS('الوحدات'!L:L, 'الوحدات'!B:B, B16, 'الوحدات'!M:M, "مباعة"), "") -> 0 | AF16: =IFERROR(MINIFS('الوحدات'!L:L, 'الوحدات'!B:B, B16), "") -> 1599000 | AG16: =IFERROR(MINIFS('الوحدات'!L:L, 'الوحدات'!B:B, B16, 'الوحدات'!M:M, "متاحة"), "") -> 0 | AH16: =IFERROR(MAXIFS('الوحدات'!L:L, 'الوحدات'!B:B, B16), "") -> 1879000 | AI16: =IFERROR(MAXIFS('الوحدات'!L:L, 'الوحدات'!B:B, B16, 'الوحدات'!M:M, "متاحة"), "") -> 0 | AJ16: =AH16&"-"&AF16 -> 1879000-1599000 | AK16: =AI16&"-"&AG16 -> 0-0 | AL16: =IFERROR(MINIFS('الوحدات'!K:K, 'الوحدات'!B:B, B16), "") -> 99 | AM16: =IFERROR(MINIFS('الوحدات'!K:K, 'الوحدات'!B:B, B16, 'الوحدات'!M:M, "متاحة"), "") -> 0 | AN16: =IFERROR(MAXIFS('الوحدات'!K:K, 'الوحدات'!B:B, B16), "") -> 137 | AO16: =IFERROR(MAXIFS('الوحدات'!K:K, 'الوحدات'!B:B, B16, 'الوحدات'!M:M, "متاحة"), "") -> 0 | AP16: =AN16&"-"&AL16 -> 137-99 | AQ16: =AO16&"-"&AM16 -> 0-0 | AR16: =IFERROR(MINIFS('الوحدات'!N:N, 'الوحدات'!B:B, B16), "") -> 2 | AS16: =IFERROR(MINIFS('الوحدات'!N:N, 'الوحدات'!B:B, B16, 'الوحدات'!M:M, "متاحة"), "") -> 0 | AT16: =IFERROR(MAXIFS('الوحدات'!N:N, 'الوحدات'!B:B, B16), "") -> 3 | AU16: =IFERROR(MAXIFS('الوحدات'!N:N, 'الوحدات'!B:B, B16, 'الوحدات'!M:M, "متاحة"), "") -> 0 | AV16: =AT16&"-"&AR16 -> 3-2 | AW16: =AU16&"-"&AS16 -> 0-0 | AX16: =IFERROR(MINIFS('الوحدات'!O:O, 'الوحدات'!B:B, B16), "") -> 3 | AY16: =IFERROR(MINIFS('الوحدات'!O:O, 'الوحدات'!B:B, B16, 'الوحدات'!M:M, "متاحة"), "") -> 0 | AZ16: =IFERROR(MAXIFS('الوحدات'!O:O, 'الوحدات'!B:B, B16), "") -> 4 | BA16: =IFERROR(MAXIFS('الوحدات'!O:O, 'الوحدات'!B:B, B16, 'الوحدات'!M:M, "متاحة"), "") -> 0 | BB16: =AZ16&"-"&AX16 -> 4-3 | BC16: =BA16&"-"&AY16 -> 0-0
A17: 16 | B17: ALN104 | C17: ألين | D17: 104 | E17: ="ألين - "&D17 -> ألين - 104 | F17: =IF(COUNTIFS('الوحدات'!B:B,B17,'الوحدات'!M:M,"متاحة")>0,"متاح", IF(COUNTIFS('الوحدات'!B:B,B17,'الوحدات'!M:M,"<>")=0, "", IF(COUNTIFS('الوحدات'!B:B,B17,'الوحدات'!M:M,"تحت الإنشاء")=COUNTIFS('الوحدات'!B:B,B17,'الوحدات'!M:M,"<>"), "تحت الإنشاء", IF(COUNTIFS('الوحدات'!B:B,B17,'الوحدات'!M:M,"تحت الإنشاء")>0, "تحت الإنشاء جزئيا", "مباعة" )))) -> تحت الإنشاء جزئيا | G17: =IFERROR(__xludf.DUMMYFUNCTION("IF(SUMPRODUCT(('الوحدات'!B:B=B17)*REGEXMATCH(TRIM('الوحدات'!J:J),""^(تاون هاوس|دور|شقة|فيلا)$""))>0,""سكني"","""")"),"سكني") -> سكني | H17: =IFERROR(__xludf.DUMMYFUNCTION("TEXTJOIN(""-"", TRUE, UNIQUE(FILTER('الوحدات'!J:J, 'الوحدات'!B:B = B17))) "),"شقة") -> شقة | J17: https://maps.app.goo.gl/vztQFdMWUJ729zNeA | K17: شمال | L17: المملكة العربية السعودية | M17: الرياض | N17: المغرزات | O17: https://aleen.cc/Upload/104/details.pdf | S17: =COUNTIF('الوحدات'!B:B, B17) -> 3 | T17: =COUNTIFS('الوحدات'!B:B, B17, 'الوحدات'!M:M, "متاحة") -> 0 | U17: =COUNTIFS('الوحدات'!B:B, B17, 'الوحدات'!M:M, "تحت الإنشاء") -> 1 | V17: =COUNTIFS('الوحدات'!B:B, B17, 'الوحدات'!M:M, "محجوزة") -> 0 | W17: =COUNTIFS('الوحدات'!B:B, B17, 'الوحدات'!M:M, "مباعة") -> 2 | X17: =IFERROR(AVERAGEIFS('الوحدات'!L:L, 'الوحدات'!B:B, B17), "") -> 1945666.7 | Y17: =IFERROR(AVERAGEIFS('الوحدات'!L:L, 'الوحدات'!B:B, B17, 'الوحدات'!M:M, "متاحة"), "") | Z17: =IFERROR(SUMIFS('الوحدات'!L:L, 'الوحدات'!B:B, B17), "") -> 5837000 | AA17: =AE17/Z17 -> 0.68494089 | AB17: =IFERROR(SUMIFS('الوحدات'!L:L, 'الوحدات'!B:B, B17, 'الوحدات'!M:M, "تحت الإنشاء"), "") -> 1839000 | AC17: =IFERROR(SUMIFS('الوحدات'!L:L, 'الوحدات'!B:B, B17, 'الوحدات'!M:M, "متاحة"), "") -> 0 | AD17: =IFERROR(SUMIFS('الوحدات'!L:L, 'الوحدات'!B:B, B17, 'الوحدات'!M:M, "محجوزة"), "") -> 0 | AE17: =IFERROR(SUMIFS('الوحدات'!L:L, 'الوحدات'!B:B, B17, 'الوحدات'!M:M, "مباعة"), "") -> 3998000 | AF17: =IFERROR(MINIFS('الوحدات'!L:L, 'الوحدات'!B:B, B17), "") -> 1839000 | AG17: =IFERROR(MINIFS('الوحدات'!L:L, 'الوحدات'!B:B, B17, 'الوحدات'!M:M, "متاحة"), "") -> 0 | AH17: =IFERROR(MAXIFS('الوحدات'!L:L, 'الوحدات'!B:B, B17), "") -> 1999000 | AI17: =IFERROR(MAXIFS('الوحدات'!L:L, 'الوحدات'!B:B, B17, 'الوحدات'!M:M, "متاحة"), "") -> 0 | AJ17: =AH17&"-"&AF17 -> 1999000-1839000 | AK17: =AI17&"-"&AG17 -> 0-0 | AL17: =IFERROR(MINIFS('الوحدات'!K:K, 'الوحدات'!B:B, B17), "") -> 149 | AM17: =IFERROR(MINIFS('الوحدات'!K:K, 'الوحدات'!B:B, B17, 'الوحدات'!M:M, "متاحة"), "") -> 0 | AN17: =IFERROR(MAXIFS('الوحدات'!K:K, 'الوحدات'!B:B, B17), "") -> 164 | AO17: =IFERROR(MAXIFS('الوحدات'!K:K, 'الوحدات'!B:B, B17, 'الوحدات'!M:M, "متاحة"), "") -> 0 | AP17: =AN17&"-"&AL17 -> 164-149 | AQ17: =AO17&"-"&AM17 -> 0-0 | AR17: =IFERROR(MINIFS('الوحدات'!N:N, 'الوحدات'!B:B, B17), "") -> 4 | AS17: =IFERROR(MINIFS('الوحدات'!N:N, 'الوحدات'!B:B, B17, 'الوحدات'!M:M, "متاحة"), "") -> 0 | AT17: =IFERROR(MAXIFS('الوحدات'!N:N, 'الوحدات'!B:B, B17), "") -> 4 | AU17: =IFERROR(MAXIFS('الوحدات'!N:N, 'الوحدات'!B:B, B17, 'الوحدات'!M:M, "متاحة"), "") -> 0 | AV17: =AT17&"-"&AR17 -> 4-4 | AW17: =AU17&"-"&AS17 -> 0-0 | AX17: =IFERROR(MINIFS('الوحدات'!O:O, 'الوحدات'!B:B, B17), "") -> 3 | AY17: =IFERROR(MINIFS('الوحدات'!O:O, 'الوحدات'!B:B, B17, 'الوحدات'!M:M, "متاحة"), "") -> 0 | AZ17: =IFERROR(MAXIFS('الوحدات'!O:O, 'الوحدات'!B:B, B17), "") -> 3 | BA17: =IFERROR(MAXIFS('الوحدات'!O:O, 'الوحدات'!B:B, B17, 'الوحدات'!M:M, "متاحة"), "") -> 0 | BB17: =AZ17&"-"&AX17 -> 3-3 | BC17: =BA17&"-"&AY17 -> 0-0
